Workbook

Sheet Summary
A1: 5-Year DCF Models — AI Infrastructure & Data Platforms
A2: Valuation date: August 24, 2026. Prices = latest close/quote per tab. Green cells link live to each company tab; edit assumptions there (yellow cells).
A4: Ticker | B4: Company | C4: Ccy | D4: Price | E4: DCF value/sh | F4: Upside/(dn) | G4: Rev CAGR y1–5 | H4: Yr-5 EBIT mgn | I4: WACC | J4: Term. g | K4: Term. mgn | L4: TV % of EV | M4: Fiscal window
A5: NTNX | B5: Nutanix | C5: US$ | D5: =NTNX!B5 -> 67.35 | E5: =NTNX!B48 -> 39.637185 | F5: =NTNX!B50 -> -0.41147461 | G5: =POWER(NTNX!G15/NTNX!B15,1/5)-1 -> 0.14088375 | H5: =NTNX!G17 -> 0.18 | I5: =NTNX!B9 -> 0.1 | J5: =NTNX!B10 -> 0.03 | K5: =NTNX!B35 -> 0.16 | L5: =NTNX!B45 -> 0.78226768 | M5: FY2026E → FY2031E
A6: P | B6: Everpure (fka Pure Storage) | C6: US$ | D6: =EVERPURE!B5 -> 112.32 | E6: =EVERPURE!B48 -> 35.855317 | F6: =EVERPURE!B50 -> -0.68077531 | G6: =POWER(EVERPURE!G15/EVERPURE!B15,1/5)-1 -> 0.16941851 | H6: =EVERPURE!G17 -> 0.14 | I6: =EVERPURE!B9 -> 0.105 | J6: =EVERPURE!B10 -> 0.03 | K6: =EVERPURE!B35 -> 0.13 | L6: =EVERPURE!B45 -> 0.8383818 | M6: FY2026A → FY2031E
A7: SNOW | B7: Snowflake | C7: US$ | D7: =SNOW!B5 -> 325.71 | E7: =SNOW!B48 -> 61.294743 | F7: =SNOW!B50 -> -0.81181191 | G7: =POWER(SNOW!G15/SNOW!B15,1/5)-1 -> 0.24724893 | H7: =SNOW!G17 -> 0.11 | I7: =SNOW!B9 -> 0.105 | J7: =SNOW!B10 -> 0.035 | K7: =SNOW!B35 -> 0.15 | L7: =SNOW!B45 -> 0.94654311 | M7: FY2026A → FY2031E
A8: PLTR | B8: Palantir | C8: US$ | D8: =PLTR!B5 -> 177.24 | E8: =PLTR!B48 -> 54.621617 | F8: =PLTR!B50 -> -0.69182116 | G8: =POWER(PLTR!G15/PLTR!B15,1/5)-1 -> 0.4095114 | H8: =PLTR!G17 -> 0.5 | I8: =PLTR!B9 -> 0.105 | J8: =PLTR!B10 -> 0.04 | K8: =PLTR!B35 -> 0.42 | L8: =PLTR!B45 -> 0.81504453 | M8: 2025A → 2030E
A9: NVDA | B9: NVIDIA | C9: US$ | D9: =NVDA!B5 -> 210.24 | E9: =NVDA!B48 -> 153.91043 | F9: =NVDA!B50 -> -0.26792986 | G9: =POWER(NVDA!G15/NVDA!B15,1/5)-1 -> 0.27023029 | H9: =NVDA!G17 -> 0.56 | I9: =NVDA!B9 -> 0.11 | J9: =NVDA!B10 -> 0.035 | K9: =NVDA!B35 -> 0.44 | L9: =NVDA!B45 -> 0.72989135 | M9: FY2026A → FY2031E
A10: AMD | B10: AMD | C10: US$ | D10: =AMD!B5 -> 473.25 | E10: =AMD!B48 -> 224.31135 | F10: =AMD!B50 -> -0.52601934 | G10: =POWER(AMD!G15/AMD!B15,1/5)-1 -> 0.32793845 | H10: =AMD!G17 -> 0.31 | I10: =AMD!B9 -> 0.115 | J10: =AMD!B10 -> 0.035 | K10: =AMD!B35 -> 0.26 | L10: =AMD!B45 -> 0.8074524 | M10: 2025A → 2030E
A11: 000660 | B11: SK hynix | C11: ₩ | D11: =SKHYNIX!B5 -> 1730000 | E11: =SKHYNIX!B48 -> 1049118.7 | F11: =SKHYNIX!B50 -> -0.39357302 | G11: =POWER(SKHYNIX!G15/SKHYNIX!B15,1/5)-1 -> 0.24765121 | H11: =SKHYNIX!G17 -> 0.44 | I11: =SKHYNIX!B9 -> 0.125 | J11: =SKHYNIX!B10 -> 0.025 | K11: =SKHYNIX!B35 -> 0.15 | L11: =SKHYNIX!B45 -> 0.38226425 | M11: 2025A → 2030E
A12: 005930 | B12: Samsung Electronics | C12: ₩ | D12: =SAMSUNG!B5 -> 256500 | E12: =SAMSUNG!B48 -> 186835.97 | F12: =SAMSUNG!B50 -> -0.27159465 | G12: =POWER(SAMSUNG!G15/SAMSUNG!B15,1/5)-1 -> 0.12826121 | H12: =SAMSUNG!G17 -> 0.26 | I12: =SAMSUNG!B9 -> 0.115 | J12: =SAMSUNG!B10 -> 0.025 | K12: =SAMSUNG!B35 -> 0.11 | L12: =SAMSUNG!B45 -> 0.44203928 | M12: 2025A → 2030E
A13: SNDK | B13: Sandisk | C13: US$ | D13: =SNDK!B5 -> 1596.08 | E13: =SNDK!B48 -> 1137.4097 | F13: =SNDK!B50 -> -0.28737302 | G13: =POWER(SNDK!G15/SNDK!B15,1/5)-1 -> 0.23196666 | H13: =SNDK!G17 -> 0.48 | I13: =SNDK!B9 -> 0.125 | J13: =SNDK!B10 -> 0.03 | K13: =SNDK!B35 -> 0.22 | L13: =SNDK!B45 -> 0.47043431 | M13: FY2026A → FY2031E
A14: 285A | B14: Kioxia Holdings | C14: ¥ | D14: =KIOXIA!B5 -> 53500 | E14: =KIOXIA!B48 -> 45434.105 | F14: =KIOXIA!B50 -> -0.1507644 | G14: =POWER(KIOXIA!G15/KIOXIA!B15,1/5)-1 -> 0.30831785 | H14: =KIOXIA!G17 -> 0.5 | I14: =KIOXIA!B9 -> 0.115 | J14: =KIOXIA!B10 -> 0.02 | K14: =KIOXIA!B35 -> 0.17 | L14: =KIOXIA!B45 -> 0.40405703 | M14: FY2025A → FY2030E
A16: Economic EBIT margins treat stock-based compensation as a real expense (between GAAP and non-GAAP operating margin) — see ReadMe. KRW/JPY names valued in local currency.

Sheet NTNX
A1: Nutanix (NASDAQ: NTNX) — 5-Year DCF
A2: Valuation date: August 24, 2026 | All figures in US$ millions unless noted | FY ends Jul 31; base = FY2026E (guide midpoint; Q4 reports Aug 26, 2026)
A4: KEY INPUTS (blue = hardcoded input; yellow = key levers)
A5: Current share price (US$) | B5: 67.35 | C5: Aug 24, 2026 quote
A6: Diluted shares outstanding (mm) | B6: 287 | C6: wtd diluted Q3 FY26 (incl. converts); 270.3mm Class A outstanding
A7: Net cash / (net debt), $mm | B7: 655 | C7: $2,018mm cash+ST inv − $1,362.5mm converts (2027+2029), Apr 30, 2026
A8: Tax rate on EBIT | B8: 0.2 | C8: GAAP ETR ~11% (NOLs); normalized
A9: WACC (discount rate) | B9: 0.1
A10: Terminal growth rate | B10: 0.03
A11: Per-share unit factor ($mm → US$/sh) | B11: 1 | C11: 1 for $mm & mm shares; 1,000 for ₩bn/¥bn & mm shares
A13: PROJECTIONS
A14: $mm | B14: FY2026E | C14: FY2027E | D14: FY2028E | E14: FY2029E | F14: FY2030E | G14: FY2031E
A15: Revenue | B15: 2830 | C15: =B15*(1+C16) -> 3155.45 | D15: =C15*(1+D16) -> 3565.6585 | E15: =D15*(1+E16) -> 4100.5073 | F15: =E15*(1+F16) -> 4756.5884 | G15: =F15*(1+G16) -> 5470.0767
A16: Revenue growth % | B16: 0.115 | C16: 0.115 | D16: 0.13 | E16: 0.15 | F16: 0.16 | G16: 0.15
A17: EBIT margin % (economic, incl. SBC) | B17: 0.09 | C17: 0.1 | D17: 0.12 | E17: 0.14 | F17: 0.16 | G17: 0.18
A18: EBIT | B18: =B15*B17 -> 254.7 | C18: =C15*C17 -> 315.545 | D18: =D15*D17 -> 427.87902 | E18: =E15*E17 -> 574.07102 | F18: =F15*F17 -> 761.05415 | G18: =G15*G17 -> 984.61381
A19: Cash taxes on EBIT | C19: =-C18*$B$8 -> -63.109 | D19: =-D18*$B$8 -> -85.575804 | E19: =-E18*$B$8 -> -114.8142 | F19: =-F18*$B$8 -> -152.21083 | G19: =-G18*$B$8 -> -196.92276
A20: NOPAT | C20: =C18+C19 -> 252.436 | D20: =D18+D19 -> 342.30322 | E20: =E18+E19 -> 459.25681 | F20: =F18+F19 -> 608.84332 | G20: =G18+G19 -> 787.69105
A21: D&A % of revenue | C21: 0.02 | D21: 0.02 | E21: 0.02 | F21: 0.02 | G21: 0.02
A22: (+) D&A | C22: =C15*C21 -> 63.109 | D22: =D15*D21 -> 71.31317 | E22: =E15*E21 -> 82.010145 | F22: =F15*F21 -> 95.131769 | G22: =G15*G21 -> 109.40153
A23: Capex % of revenue | C23: 0.015 | D23: 0.015 | E23: 0.015 | F23: 0.015 | G23: 0.015
A24: (–) Capex | C24: =-C15*C23 -> -47.33175 | D24: =-D15*D23 -> -53.484878 | E24: =-E15*E23 -> -61.507609 | F24: =-F15*F23 -> -71.348827 | G24: =-G15*G23 -> -82.051151
A25: ΔNWC as % of Δrevenue (neg = cash source) | C25: -0.2 | D25: -0.2 | E25: -0.2 | F25: -0.2 | G25: -0.2
A26: (–) Investment in working capital | C26: =-(C15-B15)*C25 -> 65.09 | D26: =-(D15-C15)*D25 -> 82.0417 | E26: =-(E15-D15)*E25 -> 106.96976 | F26: =-(F15-E15)*F25 -> 131.21623 | G26: =-(G15-F15)*G25 -> 142.69765
A27: Unlevered free cash flow | C27: =C20+C22+C24+C26 -> 333.30325 | D27: =D20+D22+D24+D26 -> 442.17321 | E27: =E20+E22+E24+E26 -> 586.72911 | F27: =F20+F22+F24+F26 -> 763.8425 | G27: =G20+G22+G24+G26 -> 957.73908
A28: uFCF margin % | C28: =C27/C15 -> 0.1056278 | D28: =D27/D15 -> 0.12400885 | E28: =E27/E15 -> 0.14308696 | F28: =F27/F15 -> 0.16058621 | G28: =G27/G15 -> 0.17508696
A30: Discount period (mid-year conv.) | C30: 0.5 | D30: =C30+1 -> 1.5 | E30: =D30+1 -> 2.5 | F30: =E30+1 -> 3.5 | G30: =F30+1 -> 4.5
A31: Discount factor | C31: =1/POWER(1+$B$9,C30) -> 0.95346259 | D31: =1/POWER(1+$B$9,D30) -> 0.86678417 | E31: =1/POWER(1+$B$9,E30) -> 0.78798561 | F31: =1/POWER(1+$B$9,F30) -> 0.71635056 | G31: =1/POWER(1+$B$9,G30) -> 0.65122778
A32: PV of uFCF | C32: =C27*C31 -> 317.79218 | D32: =D27*D31 -> 383.26874 | E32: =E27*E31 -> 462.33409 | F32: =F27*F31 -> 547.179 | G32: =G27*G31 -> 623.70629
A34: TERMINAL VALUE (Gordon growth on normalized margin)
A35: Normalized terminal uFCF margin (× yr-5 revenue) | B35: 0.16 | C35: derived: 18% steady-state econ EBIT (28% NG OM − 10% SBC) × 0.8 tax = 14.4% + ~1.2pt deferred-rev inflow & D&A>capex
A36: Terminal uFCF (yr-5 revenue × (1+g) × margin) | B36: =G15*(1+$B$10)*B35 -> 901.46864
A37: Terminal value at end of year 5 | B37: =B36/($B$9-$B$10) -> 12878.123
A38: PV of terminal value | B38: =B37*G31 -> 8386.5917
A39: Implied terminal EV / yr-5 uFCF | B39: =B37/G27 -> 13.44638
A41: VALUATION
A42: PV of explicit-period uFCF (yrs 1–5) | B42: =SUM(C32:G32) -> 2334.2803
A43: PV of terminal value | B43: =B38 -> 8386.5917
A44: Enterprise value | B44: =B42+B43 -> 10720.872
A45: Terminal value % of EV | B45: =B43/B44 -> 0.78226768
...

Sheet EVERPURE
A1: Everpure (fka Pure Storage) (NYSE: P) — 5-Year DCF
A2: Valuation date: August 24, 2026 | All figures in US$ millions unless noted | FY ends early Feb; base = FY2026A (ended Feb 1, 2026); renamed from Pure Storage/PSTG Apr 2026
A4: KEY INPUTS (blue = hardcoded input; yellow = key levers)
A5: Current share price (US$) | B5: 112.32 | C5: Aug 19, 2026 close (post +22% pop on 2nd hyperscaler win)
A6: Diluted shares outstanding (mm) | B6: 346 | C6: non-GAAP wtd diluted Q4 FY26; ~331.5mm outstanding
A7: Net cash / (net debt), $mm | B7: 1500 | C7: cash+investments ~$1.5B, no debt (Q1 FY27)
A8: Tax rate on EBIT | B8: 0.2 | C8: normalized; NOLs keep near-term cash taxes low
A9: WACC (discount rate) | B9: 0.105
A10: Terminal growth rate | B10: 0.03
A11: Per-share unit factor ($mm → US$/sh) | B11: 1 | C11: 1 for $mm & mm shares; 1,000 for ₩bn/¥bn & mm shares
A13: PROJECTIONS
A14: $mm | B14: FY2026A | C14: FY2027E | D14: FY2028E | E14: FY2029E | F14: FY2030E | G14: FY2031E
A15: Revenue | B15: 3670 | C15: =B15*(1+C16) -> 4477.4 | D15: =C15*(1+D16) -> 5372.88 | E15: =D15*(1+E16) -> 6286.2696 | F15: =E15*(1+F16) -> 7166.3473 | G15: =F15*(1+G16) -> 8026.309
A16: Revenue growth % | B16: 0.16 | C16: 0.22 | D16: 0.2 | E16: 0.17 | F16: 0.14 | G16: 0.12
A17: EBIT margin % (economic, incl. SBC) | B17: 0.042 | C17: 0.06 | D17: 0.08 | E17: 0.1 | F17: 0.12 | G17: 0.14
A18: EBIT | B18: =B15*B17 -> 154.14 | C18: =C15*C17 -> 268.644 | D18: =D15*D17 -> 429.8304 | E18: =E15*E17 -> 628.62696 | F18: =F15*F17 -> 859.96168 | G18: =G15*G17 -> 1123.6833
A19: Cash taxes on EBIT | C19: =-C18*$B$8 -> -53.7288 | D19: =-D18*$B$8 -> -85.96608 | E19: =-E18*$B$8 -> -125.72539 | F19: =-F18*$B$8 -> -171.99234 | G19: =-G18*$B$8 -> -224.73665
A20: NOPAT | C20: =C18+C19 -> 214.9152 | D20: =D18+D19 -> 343.86432 | E20: =E18+E19 -> 502.90157 | F20: =F18+F19 -> 687.96935 | G20: =G18+G19 -> 898.94661
A21: D&A % of revenue | C21: 0.05 | D21: 0.05 | E21: 0.05 | F21: 0.05 | G21: 0.05
A22: (+) D&A | C22: =C15*C21 -> 223.87 | D22: =D15*D21 -> 268.644 | E22: =E15*E21 -> 314.31348 | F22: =F15*F21 -> 358.31737 | G22: =G15*G21 -> 401.31545
A23: Capex % of revenue | C23: 0.065 | D23: 0.065 | E23: 0.065 | F23: 0.065 | G23: 0.065
A24: (–) Capex | C24: =-C15*C23 -> -291.031 | D24: =-D15*D23 -> -349.2372 | E24: =-E15*E23 -> -408.60752 | F24: =-F15*F23 -> -465.81258 | G24: =-G15*G23 -> -521.71009
A25: ΔNWC as % of Δrevenue (neg = cash source) | C25: -0.05 | D25: -0.05 | E25: -0.05 | F25: -0.05 | G25: -0.05
A26: (–) Investment in working capital | C26: =-(C15-B15)*C25 -> 40.37 | D26: =-(D15-C15)*D25 -> 44.774 | E26: =-(E15-D15)*E25 -> 45.66948 | F26: =-(F15-E15)*F25 -> 44.003887 | G26: =-(G15-F15)*G25 -> 42.998084
A27: Unlevered free cash flow | C27: =C20+C22+C24+C26 -> 188.1242 | D27: =D20+D22+D24+D26 -> 308.04512 | E27: =E20+E22+E24+E26 -> 454.277 | F27: =F20+F22+F24+F26 -> 624.47802 | G27: =G20+G22+G24+G26 -> 821.55006
A28: uFCF margin % | C28: =C27/C15 -> 0.042016393 | D28: =D27/D15 -> 0.057333333 | E28: =E27/E15 -> 0.072264957 | F28: =F27/F15 -> 0.087140351 | G28: =G27/G15 -> 0.10235714
A30: Discount period (mid-year conv.) | C30: 0.5 | D30: =C30+1 -> 1.5 | E30: =D30+1 -> 2.5 | F30: =E30+1 -> 3.5 | G30: =F30+1 -> 4.5
A31: Discount factor | C31: =1/POWER(1+$B$9,C30) -> 0.95130299 | D31: =1/POWER(1+$B$9,D30) -> 0.86090768 | E31: =1/POWER(1+$B$9,E30) -> 0.77910197 | F31: =1/POWER(1+$B$9,F30) -> 0.70506966 | G31: =1/POWER(1+$B$9,G30) -> 0.63807209
A32: PV of uFCF | C32: =C27*C31 -> 178.96311 | D32: =D27*D31 -> 265.19841 | E32: =E27*E31 -> 353.92811 | F32: =F27*F31 -> 440.30051 | G32: =G27*G31 -> 524.20816
A34: TERMINAL VALUE (Gordon growth on normalized margin)
A35: Normalized terminal uFCF margin (× yr-5 revenue) | B35: 0.13 | C35: steady state: ~24% non-GAAP OM − ~9% SBC, taxed, + small sub inflow
A36: Terminal uFCF (yr-5 revenue × (1+g) × margin) | B36: =G15*(1+$B$10)*B35 -> 1074.7228
A37: Terminal value at end of year 5 | B37: =B36/($B$9-$B$10) -> 14329.637
A38: PV of terminal value | B38: =B37*G31 -> 9143.3415
A39: Implied terminal EV / yr-5 uFCF | B39: =B37/G27 -> 17.442196
A41: VALUATION
A42: PV of explicit-period uFCF (yrs 1–5) | B42: =SUM(C32:G32) -> 1762.5983
A43: PV of terminal value | B43: =B38 -> 9143.3415
A44: Enterprise value | B44: =B42+B43 -> 10905.94
A45: Terminal value % of EV | B45: =B43/B44 -> 0.8383818
...

Sheet SNOW
A1: Snowflake (NYSE: SNOW) — 5-Year DCF
A2: Valuation date: August 24, 2026 | All figures in US$ millions unless noted | FY ends Jan 31; base = FY2026A; total revenue basis (product ≈ 95%)
A4: KEY INPUTS (blue = hardcoded input; yellow = key levers)
A5: Current share price (US$) | B5: 325.71 | C5: Aug 24, 2026 quote; Q2 FY27 reports Sep 2, 2026
A6: Diluted shares outstanding (mm) | B6: 370 | C6: ~354mm outstanding + ~4.5% dilution
A7: Net cash / (net debt), $mm | B7: 1560 | C7: ~$3.86B cash+inv − $2.3B 0% converts (2027/2029), Apr 30, 2026
A8: Tax rate on EBIT | B8: 0.21 | C8: normalized; large NOLs defer cash taxes
A9: WACC (discount rate) | B9: 0.105
A10: Terminal growth rate | B10: 0.035
A11: Per-share unit factor ($mm → US$/sh) | B11: 1 | C11: 1 for $mm & mm shares; 1,000 for ₩bn/¥bn & mm shares
A13: PROJECTIONS
A14: $mm | B14: FY2026A | C14: FY2027E | D14: FY2028E | E14: FY2029E | F14: FY2030E | G14: FY2031E
A15: Revenue | B15: 4680 | C15: =B15*(1+C16) -> 6084 | D15: =C15*(1+D16) -> 7787.52 | E15: =D15*(1+E16) -> 9812.2752 | F15: =E15*(1+F16) -> 11970.976 | G15: =F15*(1+G16) -> 14125.751
A16: Revenue growth % | B16: 0.29 | C16: 0.3 | D16: 0.28 | E16: 0.26 | F16: 0.22 | G16: 0.18
A17: EBIT margin % (economic, incl. SBC) | B17: -0.195 | C17: -0.14 | D17: -0.06 | E17: 0 | F17: 0.06 | G17: 0.11
A18: EBIT | B18: =B15*B17 -> -912.6 | C18: =C15*C17 -> -851.76 | D18: =D15*D17 -> -467.2512 | E18: =E15*E17 -> 0 | F18: =F15*F17 -> 718.25854 | G18: =G15*G17 -> 1553.8327
A19: Cash taxes on EBIT | C19: =-C18*$B$8 -> 178.8696 | D19: =-D18*$B$8 -> 98.122752 | E19: =-E18*$B$8 -> 0 | F19: =-F18*$B$8 -> -150.83429 | G19: =-G18*$B$8 -> -326.30486
A20: NOPAT | C20: =C18+C19 -> -672.8904 | D20: =D18+D19 -> -369.12845 | E20: =E18+E19 -> 0 | F20: =F18+F19 -> 567.42425 | G20: =G18+G19 -> 1227.5278
A21: D&A % of revenue | C21: 0.03 | D21: 0.03 | E21: 0.03 | F21: 0.03 | G21: 0.03
A22: (+) D&A | C22: =C15*C21 -> 182.52 | D22: =D15*D21 -> 233.6256 | E22: =E15*E21 -> 294.36826 | F22: =F15*F21 -> 359.12927 | G22: =G15*G21 -> 423.77254
A23: Capex % of revenue | C23: 0.035 | D23: 0.035 | E23: 0.035 | F23: 0.035 | G23: 0.035
A24: (–) Capex | C24: =-C15*C23 -> -212.94 | D24: =-D15*D23 -> -272.5632 | E24: =-E15*E23 -> -343.42963 | F24: =-F15*F23 -> -418.98415 | G24: =-G15*G23 -> -494.4013
A25: ΔNWC as % of Δrevenue (neg = cash source) | C25: -0.15 | D25: -0.15 | E25: -0.15 | F25: -0.15 | G25: -0.15
A26: (–) Investment in working capital | C26: =-(C15-B15)*C25 -> 210.6 | D26: =-(D15-C15)*D25 -> 255.528 | E26: =-(E15-D15)*E25 -> 303.71328 | F26: =-(F15-E15)*F25 -> 323.80508 | G26: =-(G15-F15)*G25 -> 323.21635
A27: Unlevered free cash flow | C27: =C20+C22+C24+C26 -> -492.7104 | D27: =D20+D22+D24+D26 -> -152.53805 | E27: =E20+E22+E24+E26 -> 254.6519 | F27: =F20+F22+F24+F26 -> 831.37445 | G27: =G20+G22+G24+G26 -> 1480.1154
A28: uFCF margin % | C28: =C27/C15 -> -0.080984615 | D28: =D27/D15 -> -0.0195875 | E28: =E27/E15 -> 0.025952381 | F28: =F27/F15 -> 0.06944918 | G28: =G27/G15 -> 0.10478136
A30: Discount period (mid-year conv.) | C30: 0.5 | D30: =C30+1 -> 1.5 | E30: =D30+1 -> 2.5 | F30: =E30+1 -> 3.5 | G30: =F30+1 -> 4.5
A31: Discount factor | C31: =1/POWER(1+$B$9,C30) -> 0.95130299 | D31: =1/POWER(1+$B$9,D30) -> 0.86090768 | E31: =1/POWER(1+$B$9,E30) -> 0.77910197 | F31: =1/POWER(1+$B$9,F30) -> 0.70506966 | G31: =1/POWER(1+$B$9,G30) -> 0.63807209
A32: PV of uFCF | C32: =C27*C31 -> -468.71688 | D32: =D27*D31 -> -131.32118 | E32: =E27*E31 -> 198.3998 | F32: =F27*F31 -> 586.1769 | G32: =G27*G31 -> 944.42032
A34: TERMINAL VALUE (Gordon growth on normalized margin)
A35: Normalized terminal uFCF margin (× yr-5 revenue) | B35: 0.15 | C35: band 12–18%: Investor-Day glidepath (30% NG OM − 15% SBC, taxed, + inflows) derives ~12%; 18% needs ~35% NG OM at scale. Base = midpoint 15%
A36: Terminal uFCF (yr-5 revenue × (1+g) × margin) | B36: =G15*(1+$B$10)*B35 -> 2193.0229
A37: Terminal value at end of year 5 | B37: =B36/($B$9-$B$10) -> 31328.899
A38: PV of terminal value | B38: =B37*G31 -> 19990.096
A39: Implied terminal EV / yr-5 uFCF | B39: =B37/G27 -> 21.166525
A41: VALUATION
A42: PV of explicit-period uFCF (yrs 1–5) | B42: =SUM(C32:G32) -> 1128.959
A43: PV of terminal value | B43: =B38 -> 19990.096
A44: Enterprise value | B44: =B42+B43 -> 21119.055
A45: Terminal value % of EV | B45: =B43/B44 -> 0.94654311
...

Sheet PLTR
A1: Palantir (NASDAQ: PLTR) — 5-Year DCF
A2: Valuation date: August 24, 2026 | All figures in US$ millions unless noted | Calendar FY; base = 2025A; Q2 2026 reported Aug 3, 2026
A4: KEY INPUTS (blue = hardcoded input; yellow = key levers)
A5: Current share price (US$) | B5: 177.24 | C5: Aug 24, 2026 quote (52-wk $106–208)
A6: Diluted shares outstanding (mm) | B6: 2569 | C6: wtd diluted Q2 2026 (10-Q)
A7: Net cash / (net debt), $mm | B7: 9200 | C7: cash + ST Treasuries $9.2B, zero debt (Jun 30, 2026)
A8: Tax rate on EBIT | B8: 0.2 | C8: ~1.4% today (NOLs); normalized — NOLs likely consumed inside window
A9: WACC (discount rate) | B9: 0.105
A10: Terminal growth rate | B10: 0.04
A11: Per-share unit factor ($mm → US$/sh) | B11: 1 | C11: 1 for $mm & mm shares; 1,000 for ₩bn/¥bn & mm shares
A13: PROJECTIONS
A14: $mm | B14: 2025A | C14: 2026E | D14: 2027E | E14: 2028E | F14: 2029E | G14: 2030E
A15: Revenue | B15: 4480 | C15: =B15*(1+C16) -> 8153.6 | D15: =C15*(1+D16) -> 11822.72 | E15: =D15*(1+E16) -> 15960.672 | F15: =E15*(1+F16) -> 20429.66 | G15: =F15*(1+G16) -> 24924.185
A16: Revenue growth % | B16: 0.56 | C16: 0.82 | D16: 0.45 | E16: 0.35 | F16: 0.28 | G16: 0.22
A17: EBIT margin % (economic, incl. SBC) | B17: 0.38 | C17: 0.46 | D17: 0.48 | E17: 0.49 | F17: 0.5 | G17: 0.5
A18: EBIT | B18: =B15*B17 -> 1702.4 | C18: =C15*C17 -> 3750.656 | D18: =D15*D17 -> 5674.9056 | E18: =E15*E17 -> 7820.7293 | F18: =F15*F17 -> 10214.83 | G18: =G15*G17 -> 12462.093
A19: Cash taxes on EBIT | C19: =-C18*$B$8 -> -750.1312 | D19: =-D18*$B$8 -> -1134.9811 | E19: =-E18*$B$8 -> -1564.1459 | F19: =-F18*$B$8 -> -2042.966 | G19: =-G18*$B$8 -> -2492.4185
A20: NOPAT | C20: =C18+C19 -> 3000.5248 | D20: =D18+D19 -> 4539.9245 | E20: =E18+E19 -> 6256.5834 | F20: =F18+F19 -> 8171.8641 | G20: =G18+G19 -> 9969.6742
A21: D&A % of revenue | C21: 0.01 | D21: 0.01 | E21: 0.01 | F21: 0.01 | G21: 0.01
A22: (+) D&A | C22: =C15*C21 -> 81.536 | D22: =D15*D21 -> 118.2272 | E22: =E15*E21 -> 159.60672 | F22: =F15*F21 -> 204.2966 | G22: =G15*G21 -> 249.24185
A23: Capex % of revenue | C23: 0.015 | D23: 0.015 | E23: 0.015 | F23: 0.015 | G23: 0.015
A24: (–) Capex | C24: =-C15*C23 -> -122.304 | D24: =-D15*D23 -> -177.3408 | E24: =-E15*E23 -> -239.41008 | F24: =-F15*F23 -> -306.4449 | G24: =-G15*G23 -> -373.86278
A25: ΔNWC as % of Δrevenue (neg = cash source) | C25: -0.05 | D25: -0.05 | E25: -0.05 | F25: -0.05 | G25: -0.05
A26: (–) Investment in working capital | C26: =-(C15-B15)*C25 -> 183.68 | D26: =-(D15-C15)*D25 -> 183.456 | E26: =-(E15-D15)*E25 -> 206.8976 | F26: =-(F15-E15)*F25 -> 223.44941 | G26: =-(G15-F15)*G25 -> 224.72626
A27: Unlevered free cash flow | C27: =C20+C22+C24+C26 -> 3143.4368 | D27: =D20+D22+D24+D26 -> 4664.2669 | E27: =E20+E22+E24+E26 -> 6383.6777 | F27: =F20+F22+F24+F26 -> 8293.1652 | G27: =G20+G22+G24+G26 -> 10069.779
A28: uFCF margin % | C28: =C27/C15 -> 0.38552747 | D28: =D27/D15 -> 0.39451724 | E28: =E27/E15 -> 0.39996296 | F28: =F27/F15 -> 0.4059375 | G28: =G27/G15 -> 0.40401639
A30: Discount period (mid-year conv.) | C30: 0.5 | D30: =C30+1 -> 1.5 | E30: =D30+1 -> 2.5 | F30: =E30+1 -> 3.5 | G30: =F30+1 -> 4.5
A31: Discount factor | C31: =1/POWER(1+$B$9,C30) -> 0.95130299 | D31: =1/POWER(1+$B$9,D30) -> 0.86090768 | E31: =1/POWER(1+$B$9,E30) -> 0.77910197 | F31: =1/POWER(1+$B$9,F30) -> 0.70506966 | G31: =1/POWER(1+$B$9,G30) -> 0.63807209
A32: PV of uFCF | C32: =C27*C31 -> 2990.3608 | D32: =D27*D31 -> 4015.5032 | E32: =E27*E31 -> 4973.5359 | F32: =F27*F31 -> 5847.2591 | G32: =G27*G31 -> 6425.2453
A34: TERMINAL VALUE (Gordon growth on normalized margin)
A35: Normalized terminal uFCF margin (× yr-5 revenue) | B35: 0.42 | C35: ~52% economic EBIT taxed + inflows; near current adj-FCF economics
A36: Terminal uFCF (yr-5 revenue × (1+g) × margin) | B36: =G15*(1+$B$10)*B35 -> 10886.884
A37: Terminal value at end of year 5 | B37: =B36/($B$9-$B$10) -> 167490.53
A38: PV of terminal value | B38: =B37*G31 -> 106871.03
A39: Implied terminal EV / yr-5 uFCF | B39: =B37/G27 -> 16.632988
A41: VALUATION
A42: PV of explicit-period uFCF (yrs 1–5) | B42: =SUM(C32:G32) -> 24251.904
A43: PV of terminal value | B43: =B38 -> 106871.03
A44: Enterprise value | B44: =B42+B43 -> 131122.93
A45: Terminal value % of EV | B45: =B43/B44 -> 0.81504453
...

Sheet NVDA
A1: NVIDIA (NASDAQ: NVDA) — 5-Year DCF
A2: Valuation date: August 24, 2026 | All figures in US$ millions unless noted | FY ends late Jan; base = FY2026A (ended Jan 25, 2026); Q2 FY27 reports Aug 26, 2026
A4: KEY INPUTS (blue = hardcoded input; yellow = key levers)
A5: Current share price (US$) | B5: 210.24 | C5: Aug 24, 2026 quote; mkt cap ~$5.2T
A6: Diluted shares outstanding (mm) | B6: 24400 | C6: implied diluted (Q1 FY27 NI $58.3B / $2.39 EPS)
A7: Net cash / (net debt), $mm | B7: 41900 | C7: $50.3B cash+securities − $8.5B debt (Apr 26, 2026); excl. equity stakes
A8: Tax rate on EBIT | B8: 0.17 | C8: FY27 guide 16–18%
A9: WACC (discount rate) | B9: 0.11
A10: Terminal growth rate | B10: 0.035
A11: Per-share unit factor ($mm → US$/sh) | B11: 1 | C11: 1 for $mm & mm shares; 1,000 for ₩bn/¥bn & mm shares
A13: PROJECTIONS
A14: $mm | B14: FY2026A | C14: FY2027E | D14: FY2028E | E14: FY2029E | F14: FY2030E | G14: FY2031E
A15: Revenue | B15: 215900 | C15: =B15*(1+C16) -> 390779 | D15: =C15*(1+D16) -> 500197.12 | E15: =D15*(1+E16) -> 590232.6 | F15: =E15*(1+F16) -> 661060.51 | G15: =F15*(1+G16) -> 713945.35
A16: Revenue growth % | B16: 0.65 | C16: 0.81 | D16: 0.28 | E16: 0.18 | F16: 0.12 | G16: 0.08
A17: EBIT margin % (economic, incl. SBC) | B17: 0.58 | C17: 0.62 | D17: 0.62 | E17: 0.6 | F17: 0.58 | G17: 0.56
A18: EBIT | B18: =B15*B17 -> 125222 | C18: =C15*C17 -> 242282.98 | D18: =D15*D17 -> 310122.21 | E18: =E15*E17 -> 354139.56 | F18: =F15*F17 -> 383415.1 | G18: =G15*G17 -> 399809.4
A19: Cash taxes on EBIT | C19: =-C18*$B$8 -> -41188.107 | D19: =-D18*$B$8 -> -52720.776 | E19: =-E18*$B$8 -> -60203.725 | F19: =-F18*$B$8 -> -65180.567 | G19: =-G18*$B$8 -> -67967.598
A20: NOPAT | C20: =C18+C19 -> 201094.87 | D20: =D18+D19 -> 257401.44 | E20: =E18+E19 -> 293935.84 | F20: =F18+F19 -> 318234.53 | G20: =G18+G19 -> 331841.8
A21: D&A % of revenue | C21: 0.025 | D21: 0.025 | E21: 0.025 | F21: 0.025 | G21: 0.025
A22: (+) D&A | C22: =C15*C21 -> 9769.475 | D22: =D15*D21 -> 12504.928 | E22: =E15*E21 -> 14755.815 | F22: =F15*F21 -> 16526.513 | G22: =G15*G21 -> 17848.634
A23: Capex % of revenue | C23: 0.035 | D23: 0.035 | E23: 0.035 | F23: 0.035 | G23: 0.035
A24: (–) Capex | C24: =-C15*C23 -> -13677.265 | D24: =-D15*D23 -> -17506.899 | E24: =-E15*E23 -> -20658.141 | F24: =-F15*F23 -> -23137.118 | G24: =-G15*G23 -> -24988.087
A25: ΔNWC as % of Δrevenue (neg = cash source) | C25: 0.1 | D25: 0.1 | E25: 0.1 | F25: 0.1 | G25: 0.1
A26: (–) Investment in working capital | C26: =-(C15-B15)*C25 -> -17487.9 | D26: =-(D15-C15)*D25 -> -10941.812 | E26: =-(E15-D15)*E25 -> -9003.5482 | F26: =-(F15-E15)*F25 -> -7082.7912 | G26: =-(G15-F15)*G25 -> -5288.4841
A27: Unlevered free cash flow | C27: =C20+C22+C24+C26 -> 179699.18 | D27: =D20+D22+D24+D26 -> 241457.65 | E27: =E20+E22+E24+E26 -> 279029.96 | F27: =F20+F22+F24+F26 -> 304541.13 | G27: =G20+G22+G24+G26 -> 319413.86
A28: uFCF margin % | C28: =C27/C15 -> 0.45984862 | D28: =D27/D15 -> 0.482725 | E28: =E27/E15 -> 0.47274576 | F28: =F27/F15 -> 0.46068571 | G28: =G27/G15 -> 0.44739259
A30: Discount period (mid-year conv.) | C30: 0.5 | D30: =C30+1 -> 1.5 | E30: =D30+1 -> 2.5 | F30: =E30+1 -> 3.5 | G30: =F30+1 -> 4.5
A31: Discount factor | C31: =1/POWER(1+$B$9,C30) -> 0.949158 | D31: =1/POWER(1+$B$9,D30) -> 0.85509729 | E31: =1/POWER(1+$B$9,E30) -> 0.77035792 | F31: =1/POWER(1+$B$9,F30) -> 0.69401615 | G31: =1/POWER(1+$B$9,G30) -> 0.62523977
A32: PV of uFCF | C32: =C27*C31 -> 170562.92 | D32: =D27*D31 -> 206469.79 | E32: =E27*E31 -> 214952.94 | F32: =F27*F31 -> 211356.46 | G32: =G27*G31 -> 199710.25
A34: TERMINAL VALUE (Gordon growth on normalized margin)
A35: Normalized terminal uFCF margin (× yr-5 revenue) | B35: 0.44 | C35: ≈ 56% EBIT taxed less reinvestment — near current FCF conversion
A36: Terminal uFCF (yr-5 revenue × (1+g) × margin) | B36: =G15*(1+$B$10)*B35 -> 325130.71
A37: Terminal value at end of year 5 | B37: =B36/($B$9-$B$10) -> 4335076.2
A38: PV of terminal value | B38: =B37*G31 -> 2710462
A39: Implied terminal EV / yr-5 uFCF | B39: =B37/G27 -> 13.571973
A41: VALUATION
A42: PV of explicit-period uFCF (yrs 1–5) | B42: =SUM(C32:G32) -> 1003052.4
A43: PV of terminal value | B43: =B38 -> 2710462
A44: Enterprise value | B44: =B42+B43 -> 3713514.4
A45: Terminal value % of EV | B45: =B43/B44 -> 0.72989135
...

Sheet AMD
A1: AMD (NASDAQ: AMD) — 5-Year DCF
A2: Valuation date: August 24, 2026 | All figures in US$ millions unless noted | Calendar FY; base = 2025A; Q2 2026 reported Aug 4, 2026
A4: KEY INPUTS (blue = hardcoded input; yellow = key levers)
A5: Current share price (US$) | B5: 473.25 | C5: Aug 24, 2026 quote; mkt cap ~$760B
A6: Diluted shares outstanding (mm) | B6: 1670 | C6: wtd diluted Q2 2026; excl. up to 160mm OpenAI warrants
A7: Net cash / (net debt), $mm | B7: 9900 | C7: $13.1B cash+ST inv − $3.25B debt (Jun 27, 2026)
A8: Tax rate on EBIT | B8: 0.14 | C8: non-GAAP rate 13% guided
A9: WACC (discount rate) | B9: 0.115
A10: Terminal growth rate | B10: 0.035
A11: Per-share unit factor ($mm → US$/sh) | B11: 1 | C11: 1 for $mm & mm shares; 1,000 for ₩bn/¥bn & mm shares
A13: PROJECTIONS
A14: $mm | B14: 2025A | C14: 2026E | D14: 2027E | E14: 2028E | F14: 2029E | G14: 2030E
A15: Revenue | B15: 34600 | C15: =B15*(1+C16) -> 49478 | D15: =C15*(1+D16) -> 68279.64 | E15: =D15*(1+E16) -> 91494.718 | F15: =E15*(1+F16) -> 117113.24 | G15: =F15*(1+G16) -> 142878.15
A16: Revenue growth % | B16: 0.34 | C16: 0.43 | D16: 0.38 | E16: 0.34 | F16: 0.28 | G16: 0.22
A17: EBIT margin % (economic, incl. SBC) | B17: 0.18 | C17: 0.225 | D17: 0.25 | E17: 0.275 | F17: 0.295 | G17: 0.31
A18: EBIT | B18: =B15*B17 -> 6228 | C18: =C15*C17 -> 11132.55 | D18: =D15*D17 -> 17069.91 | E18: =E15*E17 -> 25161.047 | F18: =F15*F17 -> 34548.405 | G18: =G15*G17 -> 44292.227
A19: Cash taxes on EBIT | C19: =-C18*$B$8 -> -1558.557 | D19: =-D18*$B$8 -> -2389.7874 | E19: =-E18*$B$8 -> -3522.5466 | F19: =-F18*$B$8 -> -4836.7768 | G19: =-G18*$B$8 -> -6200.9118
A20: NOPAT | C20: =C18+C19 -> 9573.993 | D20: =D18+D19 -> 14680.123 | E20: =E18+E19 -> 21638.501 | F20: =F18+F19 -> 29711.629 | G20: =G18+G19 -> 38091.315
A21: D&A % of revenue | C21: 0.03 | D21: 0.03 | E21: 0.03 | F21: 0.03 | G21: 0.03
A22: (+) D&A | C22: =C15*C21 -> 1484.34 | D22: =D15*D21 -> 2048.3892 | E22: =E15*E21 -> 2744.8415 | F22: =F15*F21 -> 3513.3972 | G22: =G15*G21 -> 4286.3445
A23: Capex % of revenue | C23: 0.035 | D23: 0.035 | E23: 0.035 | F23: 0.035 | G23: 0.035
A24: (–) Capex | C24: =-C15*C23 -> -1731.73 | D24: =-D15*D23 -> -2389.7874 | E24: =-E15*E23 -> -3202.3151 | F24: =-F15*F23 -> -4098.9633 | G24: =-G15*G23 -> -5000.7353
A25: ΔNWC as % of Δrevenue (neg = cash source) | C25: 0.12 | D25: 0.12 | E25: 0.12 | F25: 0.12 | G25: 0.12
A26: (–) Investment in working capital | C26: =-(C15-B15)*C25 -> -1785.36 | D26: =-(D15-C15)*D25 -> -2256.1968 | E26: =-(E15-D15)*E25 -> -2785.8093 | F26: =-(F15-E15)*F25 -> -3074.2225 | G26: =-(G15-F15)*G25 -> -3091.7895
A27: Unlevered free cash flow | C27: =C20+C22+C24+C26 -> 7541.243 | D27: =D20+D22+D24+D26 -> 12082.528 | E27: =E20+E22+E24+E26 -> 18395.218 | F27: =F20+F22+F24+F26 -> 26051.84 | G27: =G20+G22+G24+G26 -> 34285.135
A28: uFCF margin % | C28: =C27/C15 -> 0.15241608 | D28: =D27/D15 -> 0.17695652 | E28: =E27/E15 -> 0.20105224 | F28: =F27/F15 -> 0.22245 | G28: =G27/G15 -> 0.23996066
A30: Discount period (mid-year conv.) | C30: 0.5 | D30: =C30+1 -> 1.5 | E30: =D30+1 -> 2.5 | F30: =E30+1 -> 3.5 | G30: =F30+1 -> 4.5
A31: Discount factor | C31: =1/POWER(1+$B$9,C30) -> 0.94702745 | D31: =1/POWER(1+$B$9,D30) -> 0.84935197 | E31: =1/POWER(1+$B$9,E30) -> 0.76175065 | F31: =1/POWER(1+$B$9,F30) -> 0.68318444 | G31: =1/POWER(1+$B$9,G30) -> 0.61272147
A32: PV of uFCF | C32: =C27*C31 -> 7141.7641 | D32: =D27*D31 -> 10262.319 | E32: =E27*E31 -> 14012.569 | F32: =F27*F31 -> 17798.212 | G32: =G27*G31 -> 21007.238
A34: TERMINAL VALUE (Gordon growth on normalized margin)
A35: Normalized terminal uFCF margin (× yr-5 revenue) | B35: 0.26 | C35: ≈ 31% economic EBIT taxed less reinvestment
A36: Terminal uFCF (yr-5 revenue × (1+g) × margin) | B36: =G15*(1+$B$10)*B35 -> 38448.51
A37: Terminal value at end of year 5 | B37: =B36/($B$9-$B$10) -> 480606.38
A38: PV of terminal value | B38: =B37*G31 -> 294477.85
A39: Implied terminal EV / yr-5 uFCF | B39: =B37/G27 -> 14.017923
A41: VALUATION
A42: PV of explicit-period uFCF (yrs 1–5) | B42: =SUM(C32:G32) -> 70222.101
A43: PV of terminal value | B43: =B38 -> 294477.85
A44: Enterprise value | B44: =B42+B43 -> 364699.95
A45: Terminal value % of EV | B45: =B43/B44 -> 0.8074524
...

Sheet SKHYNIX
A1: SK hynix (KRX: 000660) — 5-Year DCF
A2: Valuation date: August 24, 2026 | All figures in KRW billions unless noted | Calendar FY; base = 2025A; H1 2026 reported Jul 29, 2026. Figures in ₩bn
A4: KEY INPUTS (blue = hardcoded input; yellow = key levers)
A5: Current share price (₩) | B5: 1730000 | C5: Aug 24, 2026 close (₩1.73M; −42% off high); ADR 'SKHY' = 1/10 share
A6: Diluted shares outstanding (mm) | B6: 728.9 | C6: common shares (mm); ₩40T buyback (3.3%) runs Aug–Nov 2026
A7: Net cash / (net debt), ₩bn | B7: 69400 | C7: ₩88.0T cash − ₩18.6T debt (Jun 30, 2026, post-Kioxia-stake sale)
A8: Tax rate on EBIT | B8: 0.22 | C8: statutory 26.4% less K-Chips credits
A9: WACC (discount rate) | B9: 0.125
A10: Terminal growth rate | B10: 0.025
A11: Per-share unit factor (₩bn → ₩/sh) | B11: 1000 | C11: 1 for $mm & mm shares; 1,000 for ₩bn/¥bn & mm shares
A13: PROJECTIONS
A14: ₩bn | B14: 2025A | C14: 2026E | D14: 2027E | E14: 2028E | F14: 2029E | G14: 2030E
A15: Revenue | B15: 97150 | C15: =B15*(1+C16) -> 316709 | D15: =C15*(1+D16) -> 364215.35 | E15: =D15*(1+E16) -> 291372.28 | F15: =E15*(1+F16) -> 262235.05 | G15: =F15*(1+G16) -> 293703.26
A16: Revenue growth % | B16: 0.468 | C16: 2.26 | D16: 0.15 | E16: -0.2 | F16: -0.1 | G16: 0.12
A17: EBIT margin % (economic, incl. SBC) | B17: 0.486 | C17: 0.74 | D17: 0.68 | E17: 0.48 | F17: 0.34 | G17: 0.44
A18: EBIT | B18: =B15*B17 -> 47214.9 | C18: =C15*C17 -> 234364.66 | D18: =D15*D17 -> 247666.44 | E18: =E15*E17 -> 139858.69 | F18: =F15*F17 -> 89159.918 | G18: =G15*G17 -> 129229.43
A19: Cash taxes on EBIT | C19: =-C18*$B$8 -> -51560.225 | D19: =-D18*$B$8 -> -54486.616 | E19: =-E18*$B$8 -> -30768.913 | F19: =-F18*$B$8 -> -19615.182 | G19: =-G18*$B$8 -> -28430.475
A20: NOPAT | C20: =C18+C19 -> 182804.43 | D20: =D18+D19 -> 193179.82 | E20: =E18+E19 -> 109089.78 | F20: =F18+F19 -> 69544.736 | G20: =G18+G19 -> 100798.96
A21: D&A % of revenue | C21: 0.08 | D21: 0.1 | E21: 0.14 | F21: 0.16 | G21: 0.14
A22: (+) D&A | C22: =C15*C21 -> 25336.72 | D22: =D15*D21 -> 36421.535 | E22: =E15*E21 -> 40792.119 | F22: =F15*F21 -> 41957.608 | G22: =G15*G21 -> 41118.456
A23: Capex % of revenue | C23: 0.13 | D23: 0.15 | E23: 0.22 | F23: 0.24 | G23: 0.18
A24: (–) Capex | C24: =-C15*C23 -> -41172.17 | D24: =-D15*D23 -> -54632.302 | E24: =-E15*E23 -> -64101.902 | F24: =-F15*F23 -> -62936.412 | G24: =-G15*G23 -> -52866.586
A25: ΔNWC as % of Δrevenue (neg = cash source) | C25: 0.12 | D25: 0.12 | E25: 0.12 | F25: 0.12 | G25: 0.12
A26: (–) Investment in working capital | C26: =-(C15-B15)*C25 -> -26347.08 | D26: =-(D15-C15)*D25 -> -5700.762 | E26: =-(E15-D15)*E25 -> 8741.1684 | F26: =-(F15-E15)*F25 -> 3496.4674 | G26: =-(G15-F15)*G25 -> -3776.1847
A27: Unlevered free cash flow | C27: =C20+C22+C24+C26 -> 140621.9 | D27: =D20+D22+D24+D26 -> 169268.29 | E27: =E20+E22+E24+E26 -> 94521.168 | F27: =F20+F22+F24+F26 -> 52062.399 | G27: =G20+G22+G24+G26 -> 85274.643
A28: uFCF margin % | C28: =C27/C15 -> 0.44400982 | D28: =D27/D15 -> 0.46474783 | E28: =E27/E15 -> 0.3244 | F28: =F27/F15 -> 0.19853333 | G28: =G27/G15 -> 0.29034286
A30: Discount period (mid-year conv.) | C30: 0.5 | D30: =C30+1 -> 1.5 | E30: =D30+1 -> 2.5 | F30: =E30+1 -> 3.5 | G30: =F30+1 -> 4.5
A31: Discount factor | C31: =1/POWER(1+$B$9,C30) -> 0.94280904 | D31: =1/POWER(1+$B$9,D30) -> 0.83805248 | E31: =1/POWER(1+$B$9,E30) -> 0.74493554 | F31: =1/POWER(1+$B$9,F30) -> 0.66216492 | G31: =1/POWER(1+$B$9,G30) -> 0.58859104
A32: PV of uFCF | C32: =C27*C31 -> 132579.6 | D32: =D27*D31 -> 141855.71 | E32: =E27*E31 -> 70412.177 | F32: =F27*F31 -> 34473.894 | G32: =G27*G31 -> 50191.891
A34: TERMINAL VALUE (Gordon growth on normalized margin)
A35: Normalized terminal uFCF margin (× yr-5 revenue) | B35: 0.15 | C35: mid-cycle: ~33% OM taxed, less structural capex>D&A gap
A36: Terminal uFCF (yr-5 revenue × (1+g) × margin) | B36: =G15*(1+$B$10)*B35 -> 45156.876
A37: Terminal value at end of year 5 | B37: =B36/($B$9-$B$10) -> 451568.76
A38: PV of terminal value | B38: =B37*G31 -> 265789.33
A39: Implied terminal EV / yr-5 uFCF | B39: =B37/G27 -> 5.2954635
A41: VALUATION
A42: PV of explicit-period uFCF (yrs 1–5) | B42: =SUM(C32:G32) -> 429513.28
A43: PV of terminal value | B43: =B38 -> 265789.33
A44: Enterprise value | B44: =B42+B43 -> 695302.61
A45: Terminal value % of EV | B45: =B43/B44 -> 0.38226425
...

Sheet SAMSUNG
A1: Samsung Electronics (KRX: 005930) — 5-Year DCF
A2: Valuation date: August 24, 2026 | All figures in KRW billions unless noted | Calendar FY; base = 2025A; H1 2026 reported Jul 30, 2026. Figures in ₩bn
A4: KEY INPUTS (blue = hardcoded input; yellow = key levers)
A5: Current share price (₩) | B5: 256500 | C5: Aug 24, 2026 close (−8.7% that day on return-plan disappointment)
A6: Diluted shares outstanding (mm) | B6: 6566 | C6: common 5,846mm + preferred 802mm (prefs valued at common price — see notes)
A7: Net cash / (net debt), ₩bn | B7: 167600 | C7: ~₩190T gross cash − ~₩22.4T debt (Jun 30, 2026), record
A8: Tax rate on EBIT | B8: 0.21 | C8: ~20% implied H1 2026 (credits)
A9: WACC (discount rate) | B9: 0.115
A10: Terminal growth rate | B10: 0.025
A11: Per-share unit factor (₩bn → ₩/sh) | B11: 1000 | C11: 1 for $mm & mm shares; 1,000 for ₩bn/¥bn & mm shares
A13: PROJECTIONS
A14: ₩bn | B14: 2025A | C14: 2026E | D14: 2027E | E14: 2028E | F14: 2029E | G14: 2030E
A15: Revenue | B15: 333610 | C15: =B15*(1+C16) -> 680564.4 | D15: =C15*(1+D16) -> 735009.55 | E15: =D15*(1+E16) -> 602707.83 | F15: =E15*(1+F16) -> 554491.21 | G15: =F15*(1+G16) -> 609940.33
A16: Revenue growth % | B16: 0.109 | C16: 1.04 | D16: 0.08 | E16: -0.18 | F16: -0.08 | G16: 0.1
A17: EBIT margin % (economic, incl. SBC) | B17: 0.131 | C17: 0.46 | D17: 0.42 | E17: 0.26 | F17: 0.18 | G17: 0.26
A18: EBIT | B18: =B15*B17 -> 43702.91 | C18: =C15*C17 -> 313059.62 | D18: =D15*D17 -> 308704.01 | E18: =E15*E17 -> 156704.04 | F18: =F15*F17 -> 99808.417 | G18: =G15*G17 -> 158584.48
A19: Cash taxes on EBIT | C19: =-C18*$B$8 -> -65742.521 | D19: =-D18*$B$8 -> -64827.842 | E19: =-E18*$B$8 -> -32907.848 | F19: =-F18*$B$8 -> -20959.768 | G19: =-G18*$B$8 -> -33302.742
A20: NOPAT | C20: =C18+C19 -> 247317.1 | D20: =D18+D19 -> 243876.17 | E20: =E18+E19 -> 123796.19 | F20: =F18+F19 -> 78848.649 | G20: =G18+G19 -> 125281.74
A21: D&A % of revenue | C21: 0.09 | D21: 0.09 | E21: 0.11 | F21: 0.12 | G21: 0.11
A22: (+) D&A | C22: =C15*C21 -> 61250.796 | D22: =D15*D21 -> 66150.86 | E22: =E15*E21 -> 66297.862 | F22: =F15*F21 -> 66538.945 | G22: =G15*G21 -> 67093.436
A23: Capex % of revenue | C23: 0.1 | D23: 0.11 | E23: 0.14 | F23: 0.15 | G23: 0.12
A24: (–) Capex | C24: =-C15*C23 -> -68056.44 | D24: =-D15*D23 -> -80851.051 | E24: =-E15*E23 -> -84379.097 | F24: =-F15*F23 -> -83173.681 | G24: =-G15*G23 -> -73192.839
A25: ΔNWC as % of Δrevenue (neg = cash source) | C25: 0.1 | D25: 0.1 | E25: 0.1 | F25: 0.1 | G25: 0.1
A26: (–) Investment in working capital | C26: =-(C15-B15)*C25 -> -34695.44 | D26: =-(D15-C15)*D25 -> -5444.5152 | E26: =-(E15-D15)*E25 -> 13230.172 | F26: =-(F15-E15)*F25 -> 4821.6627 | G26: =-(G15-F15)*G25 -> -5544.9121
A27: Unlevered free cash flow | C27: =C20+C22+C24+C26 -> 205816.02 | D27: =D20+D22+D24+D26 -> 223731.46 | E27: =E20+E22+E24+E26 -> 118945.13 | F27: =F20+F22+F24+F26 -> 67035.576 | G27: =G20+G22+G24+G26 -> 113637.43
A28: uFCF margin % | C28: =C27/C15 -> 0.30241961 | D28: =D27/D15 -> 0.30439259 | E28: =E27/E15 -> 0.19735122 | F28: =F27/F15 -> 0.12089565 | G28: =G27/G15 -> 0.18630909
A30: Discount period (mid-year conv.) | C30: 0.5 | D30: =C30+1 -> 1.5 | E30: =D30+1 -> 2.5 | F30: =E30+1 -> 3.5 | G30: =F30+1 -> 4.5
A31: Discount factor | C31: =1/POWER(1+$B$9,C30) -> 0.94702745 | D31: =1/POWER(1+$B$9,D30) -> 0.84935197 | E31: =1/POWER(1+$B$9,E30) -> 0.76175065 | F31: =1/POWER(1+$B$9,F30) -> 0.68318444 | G31: =1/POWER(1+$B$9,G30) -> 0.61272147
A32: PV of uFCF | C32: =C27*C31 -> 194913.42 | D32: =D27*D31 -> 190026.76 | E32: =E27*E31 -> 90606.526 | F32: =F27*F31 -> 45797.662 | G32: =G27*G31 -> 69628.092
A34: TERMINAL VALUE (Gordon growth on normalized margin)
A35: Normalized terminal uFCF margin (× yr-5 revenue) | B35: 0.11 | C35: mid-cycle blended: memory ~30% OM + DX low-single-digit → ~18% group OM taxed
A36: Terminal uFCF (yr-5 revenue × (1+g) × margin) | B36: =G15*(1+$B$10)*B35 -> 68770.772
A37: Terminal value at end of year 5 | B37: =B36/($B$9-$B$10) -> 764119.69
A38: PV of terminal value | B38: =B37*G31 -> 468192.54
A39: Implied terminal EV / yr-5 uFCF | B39: =B37/G27 -> 6.7241903
A41: VALUATION
A42: PV of explicit-period uFCF (yrs 1–5) | B42: =SUM(C32:G32) -> 590972.46
A43: PV of terminal value | B43: =B38 -> 468192.54
A44: Enterprise value | B44: =B42+B43 -> 1059165
A45: Terminal value % of EV | B45: =B43/B44 -> 0.44203928
...

Sheet SNDK
A1: Sandisk (NASDAQ: SNDK) — 5-Year DCF
A2: Valuation date: August 24, 2026 | All figures in US$ millions unless noted | FY ends early Jul; base = FY2026A (ended Jul 3, 2026, reported Aug 5, 2026)
A4: KEY INPUTS (blue = hardcoded input; yellow = key levers)
A5: Current share price (US$) | B5: 1596.08 | C5: Aug 21, 2026 close
A6: Diluted shares outstanding (mm) | B6: 155 | C6: ~146.4mm outstanding; ~155mm diluted (guide basis)
A7: Net cash / (net debt), $mm | B7: 4762 | C7: $4.76B cash, zero debt (Jul 3, 2026); $14B buyback authorized Aug 2026
A8: Tax rate on EBIT | B8: 0.17 | C8: implied non-GAAP ~16–18%
A9: WACC (discount rate) | B9: 0.125
A10: Terminal growth rate | B10: 0.03
A11: Per-share unit factor ($mm → US$/sh) | B11: 1 | C11: 1 for $mm & mm shares; 1,000 for ₩bn/¥bn & mm shares
A13: PROJECTIONS
A14: $mm | B14: FY2026A | C14: FY2027E | D14: FY2028E | E14: FY2029E | F14: FY2030E | G14: FY2031E
A15: Revenue | B15: 20254 | C15: =B15*(1+C16) -> 48812.14 | D15: =C15*(1+D16) -> 57598.325 | E15: =D15*(1+E16) -> 60478.241 | F15: =E15*(1+F16) -> 53220.852 | G15: =F15*(1+G16) -> 57478.521
A16: Revenue growth % | B16: 1.75 | C16: 1.41 | D16: 0.18 | E16: 0.05 | F16: -0.12 | G16: 0.08
A17: EBIT margin % (economic, incl. SBC) | B17: 0.64 | C17: 0.72 | D17: 0.66 | E17: 0.55 | F17: 0.38 | G17: 0.48
A18: EBIT | B18: =B15*B17 -> 12962.56 | C18: =C15*C17 -> 35144.741 | D18: =D15*D17 -> 38014.895 | E18: =E15*E17 -> 33263.033 | F18: =F15*F17 -> 20223.924 | G18: =G15*G17 -> 27589.69
A19: Cash taxes on EBIT | C19: =-C18*$B$8 -> -5974.6059 | D19: =-D18*$B$8 -> -6462.5321 | E19: =-E18*$B$8 -> -5654.7156 | F19: =-F18*$B$8 -> -3438.0671 | G19: =-G18*$B$8 -> -4690.2473
A20: NOPAT | C20: =C18+C19 -> 29170.135 | D20: =D18+D19 -> 31552.363 | E20: =E18+E19 -> 27608.317 | F20: =F18+F19 -> 16785.857 | G20: =G18+G19 -> 22899.443
A21: D&A % of revenue | C21: 0.06 | D21: 0.06 | E21: 0.06 | F21: 0.06 | G21: 0.06
A22: (+) D&A | C22: =C15*C21 -> 2928.7284 | D22: =D15*D21 -> 3455.8995 | E22: =E15*E21 -> 3628.6945 | F22: =F15*F21 -> 3193.2511 | G22: =G15*G21 -> 3448.7112
A23: Capex % of revenue | C23: 0.08 | D23: 0.08 | E23: 0.08 | F23: 0.08 | G23: 0.08
A24: (–) Capex | C24: =-C15*C23 -> -3904.9712 | D24: =-D15*D23 -> -4607.866 | E24: =-E15*E23 -> -4838.2593 | F24: =-F15*F23 -> -4257.6682 | G24: =-G15*G23 -> -4598.2817
A25: ΔNWC as % of Δrevenue (neg = cash source) | C25: 0.12 | D25: 0.12 | E25: 0.12 | F25: 0.12 | G25: 0.12
A26: (–) Investment in working capital | C26: =-(C15-B15)*C25 -> -3426.9768 | D26: =-(D15-C15)*D25 -> -1054.3422 | E26: =-(E15-D15)*E25 -> -345.58995 | F26: =-(F15-E15)*F25 -> 870.88668 | G26: =-(G15-F15)*G25 -> -510.92018
A27: Unlevered free cash flow | C27: =C20+C22+C24+C26 -> 24766.915 | D27: =D20+D22+D24+D26 -> 29346.054 | E27: =E20+E22+E24+E26 -> 26053.162 | F27: =F20+F22+F24+F26 -> 16592.327 | G27: =G20+G22+G24+G26 -> 21238.952
A28: uFCF margin % | C28: =C27/C15 -> 0.50739253 | D28: =D27/D15 -> 0.50949492 | E28: =E27/E15 -> 0.43078571 | F28: =F27/F15 -> 0.31176364 | G28: =G27/G15 -> 0.36951111
A30: Discount period (mid-year conv.) | C30: 0.5 | D30: =C30+1 -> 1.5 | E30: =D30+1 -> 2.5 | F30: =E30+1 -> 3.5 | G30: =F30+1 -> 4.5
A31: Discount factor | C31: =1/POWER(1+$B$9,C30) -> 0.94280904 | D31: =1/POWER(1+$B$9,D30) -> 0.83805248 | E31: =1/POWER(1+$B$9,E30) -> 0.74493554 | F31: =1/POWER(1+$B$9,F30) -> 0.66216492 | G31: =1/POWER(1+$B$9,G30) -> 0.58859104
A32: PV of uFCF | C32: =C27*C31 -> 23350.472 | D32: =D27*D31 -> 24593.533 | E32: =E27*E31 -> 19407.927 | F32: =F27*F31 -> 10986.857 | G32: =G27*G31 -> 12501.057
A34: TERMINAL VALUE (Gordon growth on normalized margin)
A35: Normalized terminal uFCF margin (× yr-5 revenue) | B35: 0.22 | C35: managed-supply mid-cycle ~30% OM taxed; old-regime NAND was ~12%
A36: Terminal uFCF (yr-5 revenue × (1+g) × margin) | B36: =G15*(1+$B$10)*B35 -> 13024.633
A37: Terminal value at end of year 5 | B37: =B36/($B$9-$B$10) -> 137101.4
A38: PV of terminal value | B38: =B37*G31 -> 80696.655
A39: Implied terminal EV / yr-5 uFCF | B39: =B37/G27 -> 6.4551866
A41: VALUATION
A42: PV of explicit-period uFCF (yrs 1–5) | B42: =SUM(C32:G32) -> 90839.845
A43: PV of terminal value | B43: =B38 -> 80696.655
A44: Enterprise value | B44: =B42+B43 -> 171536.5
A45: Terminal value % of EV | B45: =B43/B44 -> 0.47043431
...

Sheet KIOXIA
A1: Kioxia Holdings (TSE: 285A) — 5-Year DCF
A2: Valuation date: August 24, 2026 | All figures in JPY billions unless noted | FY ends Mar 31; base = FY2025A (ended Mar 31, 2026); IFRS. Figures in ¥bn; pre-split price (3:1 Oct 2026)
A4: KEY INPUTS (blue = hardcoded input; yellow = key levers)
A5: Current share price (¥) | B5: 53500 | C5: Aug 24, 2026 quote (~50% off Jul-2026 peak)
A6: Diluted shares outstanding (mm) | B6: 550 | C6: ~547–554mm; ¥800B buyback announced Jul 2026
A7: Net cash / (net debt), ¥bn | B7: 187 | C7: ¥791B cash − ~¥604B debt (Jun 30, 2026) — first net-cash position ever
A8: Tax rate on EBIT | B8: 0.31 | C8: Japan statutory ~30.6%
A9: WACC (discount rate) | B9: 0.115
A10: Terminal growth rate | B10: 0.02
A11: Per-share unit factor (¥bn → ¥/sh) | B11: 1000 | C11: 1 for $mm & mm shares; 1,000 for ₩bn/¥bn & mm shares
A13: PROJECTIONS
A14: ¥bn | B14: FY2025A | C14: FY2026E | D14: FY2027E | E14: FY2028E | F14: FY2029E | G14: FY2030E
A15: Revenue | B15: 2337.6 | C15: =B15*(1+C16) -> 9607.536 | D15: =C15*(1+D16) -> 10087.913 | E15: =D15*(1+E16) -> 8574.7259 | F15: =E15*(1+F16) -> 8145.9896 | G15: =F15*(1+G16) -> 8960.5885
A16: Revenue growth % | B16: 0.37 | C16: 3.11 | D16: 0.05 | E16: -0.15 | F16: -0.05 | G16: 0.1
A17: EBIT margin % (economic, incl. SBC) | B17: 0.372 | C17: 0.78 | D17: 0.72 | E17: 0.55 | F17: 0.4 | G17: 0.5
A18: EBIT | B18: =B15*B17 -> 869.5872 | C18: =C15*C17 -> 7493.8781 | D18: =D15*D17 -> 7263.2972 | E18: =E15*E17 -> 4716.0992 | F18: =F15*F17 -> 3258.3958 | G18: =G15*G17 -> 4480.2943
A19: Cash taxes on EBIT | C19: =-C18*$B$8 -> -2323.1022 | D19: =-D18*$B$8 -> -2251.6221 | E19: =-E18*$B$8 -> -1461.9908 | F19: =-F18*$B$8 -> -1010.1027 | G19: =-G18*$B$8 -> -1388.8912
A20: NOPAT | C20: =C18+C19 -> 5170.7759 | D20: =D18+D19 -> 5011.6751 | E20: =E18+E19 -> 3254.1085 | F20: =F18+F19 -> 2248.2931 | G20: =G18+G19 -> 3091.403
A21: D&A % of revenue | C21: 0.08 | D21: 0.08 | E21: 0.08 | F21: 0.08 | G21: 0.08
A22: (+) D&A | C22: =C15*C21 -> 768.60288 | D22: =D15*D21 -> 807.03302 | E22: =E15*E21 -> 685.97807 | F22: =F15*F21 -> 651.67917 | G22: =G15*G21 -> 716.84708
A23: Capex % of revenue | C23: 0.07 | D23: 0.07 | E23: 0.07 | F23: 0.07 | G23: 0.07
A24: (–) Capex | C24: =-C15*C23 -> -672.52752 | D24: =-D15*D23 -> -706.1539 | E24: =-E15*E23 -> -600.23081 | F24: =-F15*F23 -> -570.21927 | G24: =-G15*G23 -> -627.2412
A25: ΔNWC as % of Δrevenue (neg = cash source) | C25: 0.1 | D25: 0.1 | E25: 0.1 | F25: 0.1 | G25: 0.1
A26: (–) Investment in working capital | C26: =-(C15-B15)*C25 -> -726.9936 | D26: =-(D15-C15)*D25 -> -48.03768 | E26: =-(E15-D15)*E25 -> 151.31869 | F26: =-(F15-E15)*F25 -> 42.873629 | G26: =-(G15-F15)*G25 -> -81.459896
A27: Unlevered free cash flow | C27: =C20+C22+C24+C26 -> 4539.8576 | D27: =D20+D22+D24+D26 -> 5064.5165 | E27: =E20+E22+E24+E26 -> 3491.1744 | F27: =F20+F22+F24+F26 -> 2372.6267 | G27: =G20+G22+G24+G26 -> 3099.549
A28: uFCF margin % | C28: =C27/C15 -> 0.4725309 | D28: =D27/D15 -> 0.5020381 | E28: =E27/E15 -> 0.40714706 | F28: =F27/F15 -> 0.29126316 | G28: =G27/G15 -> 0.34590909
A30: Discount period (mid-year conv.) | C30: 0.5 | D30: =C30+1 -> 1.5 | E30: =D30+1 -> 2.5 | F30: =E30+1 -> 3.5 | G30: =F30+1 -> 4.5
A31: Discount factor | C31: =1/POWER(1+$B$9,C30) -> 0.94702745 | D31: =1/POWER(1+$B$9,D30) -> 0.84935197 | E31: =1/POWER(1+$B$9,E30) -> 0.76175065 | F31: =1/POWER(1+$B$9,F30) -> 0.68318444 | G31: =1/POWER(1+$B$9,G30) -> 0.61272147
A32: PV of uFCF | C32: =C27*C31 -> 4299.3698 | D32: =D27*D31 -> 4301.5571 | E32: =E27*E31 -> 2659.4044 | F32: =F27*F31 -> 1620.9416 | G32: =G27*G31 -> 1899.1602
A34: TERMINAL VALUE (Gordon growth on normalized margin)
A35: Normalized terminal uFCF margin (× yr-5 revenue) | B35: 0.17 | C35: mid-cycle ~28% OM at Japan tax; slightly below Sandisk on mix
A36: Terminal uFCF (yr-5 revenue × (1+g) × margin) | B36: =G15*(1+$B$10)*B35 -> 1553.7661
A37: Terminal value at end of year 5 | B37: =B36/($B$9-$B$10) -> 16355.432
A38: PV of terminal value | B38: =B37*G31 -> 10021.324
A39: Implied terminal EV / yr-5 uFCF | B39: =B37/G27 -> 5.2767135
A41: VALUATION
A42: PV of explicit-period uFCF (yrs 1–5) | B42: =SUM(C32:G32) -> 14780.433
A43: PV of terminal value | B43: =B38 -> 10021.324
A44: Enterprise value | B44: =B42+B43 -> 24801.757
A45: Terminal value % of EV | B45: =B43/B44 -> 0.40405703
...

Sheet ReadMe
A1: 5-Year DCF Models — Methodology & How to Use
A2: Built August 24, 2026. Estimates anchored to company guidance and analyst-day / investor-day targets; all base figures from latest filings and earnings releases (sources on each tab).
A4: HOW TO USE
A5: • Blue cells are hardcoded inputs; yellow-filled cells are the key levers (revenue growth, EBIT margin, WACC, terminal growth, terminal margin). Edit those — everything else recalculates.
A6: • Each company tab: inputs → 5-yr projection → terminal value → EV bridge → per-share value → WACC × terminal-growth sensitivity grid → assumption notes with sources.
A7: • The Summary tab links live to every company tab (green cells).
A9: METHODOLOGY
A10: • Unlevered DCF: uFCF = EBIT × (1 − tax) + D&A − capex − ΔNWC. EBIT margins are 'economic' margins that treat stock-based compensation as a real expense (they sit between GAAP and non-GAAP operating margins). This avoids the classic software-DCF trap of capitalizing non-GAAP FCF while ignoring SBC dilution — it is the main reason the high-SBC software names (SNOW ~29% SBC/revenue, NTNX ~13%, Everpure ~13%) show DCF values far below market. To see a street-style non-GAAP valuation instead, set the yellow margin cells to the non-GAAP operating margins quoted in each tab's notes.
A11: • Mid-year discounting convention (periods 0.5 … 4.5). For companies whose fiscal year 1 is already partly elapsed (Jan/Feb/Jun/Jul FYE), this slightly flatters PV; immaterial to conclusions.
A12: • Terminal value: Gordon growth on a NORMALIZED terminal uFCF margin × year-5 revenue. For the cyclical memory names (SK hynix, Samsung, Sandisk, Kioxia) the terminal margin is set near MID-CYCLE, not the current super-cycle peak, so the perpetuity does not capitalize peak earnings. For the software names it is set at estimated steady-state economics rather than the year-5 point on the transition path. Each margin reconciles as: steady-state economic EBIT × (1−tax) + D&A − capex − growth×NWC (the derivation is on each tab). Discounting is mid-year-consistent: PV(TV) = [TFCF/(WACC−g)] × DF(4.5) is the exact value of a perpetuity whose payments land at mid-year, matching the explicit period.
A13: • Net cash = latest-quarter cash + investments − total debt (incl. converts). Diluted shares = latest reported diluted count; future buybacks and dilution are not separately modeled.
A14: • Guidance anchors used: AMD FAD Nov-2025 (>35% rev CAGR, >60% DC CAGR, >$20 EPS in 3–5 yrs); NVIDIA ≥$1T Blackwell+Rubin bookings through CY2027 and $3–4T AI-infra TAM by 2030; Snowflake Jun-2026 Investor Day ($10B product revenue FY29 reaffirmed, GAAP-profitable by Q4 FY28, SBC 41%→27% glidepath); Nutanix mid/high-teens growth by FY29 framework; Everpure (Pure Storage) Meta ramp + 2nd hyperscaler win (Aug-2026) ahead of its Sep-23-2026 analyst day; Sandisk Aug-2026 'In Focus' investor day (FY28–30: mid/high-teens growth, ~80% GM, ~75% op margin, ~50% FCF margin — haircut here for cycle risk); Kioxia capex-discipline plan (~¥470B/yr FY26–28); SK hynix HBM commitments and Samsung memory/foundry recovery (see tabs).
... A22: • This is an analytical exercise, not investment advice.
