Workbook

Sheet README
A1: Earnings by Sector — Peer Comp Workbook
A2: Software (99 names) and Semiconductors (139 names) quarterly earnings analysis vs peers: revenue growth, $ added QoQ/YoY, margin expansion, operating leverage, FCF margin expansion, and NTM estimate revisions.
A4: HOW TO REFRESH
A5: 1. Open this file in Excel on a machine with the Bloomberg Add-in (terminal) logged in.
A6: 2. Bloomberg ribbon > Refresh All (or Ctrl+Alt+F9). The BQL spills and BDP calls will populate; the first refresh pulls ~950 BQL queries + ~1,900 BDP fields, so give it a few minutes.
A7: 3. All analysis sheets (Metrics, Dashboard, Focus) recalculate automatically from the data sheets.
A9: SHEET GUIDE
A10: Tickers — the only input sheet: both peer lists. Row order here drives every other sheet.
A11: SW/Semi Rev, OpInc, FCF — raw quarterly data via one BQL spill per ticker (FPO −13 … +2, USD mm).
A12: SW/Semi Revisions — NTM (1BF) consensus revenue & EPS now vs 1M/3M/6M ago, and the % revisions.
A13: SW/Semi Metrics — computed grids: YoY/QoQ growth, $ added, op margin & expansion, op income growth, incremental margin (operating leverage), LTM FCF margin & expansion.
A14: SW/Semi Dashboard — one row per name, latest-quarter snapshot of every metric + revision columns, with peer median / quartiles on top and color scales.
... A40: • Sorting the Dashboard keeps each row internally consistent, but re-sorting is manual after a refresh.

Sheet Tickers
A1: Ticker Lists (edit here — every other sheet reads these cells) | H1: ⚠ Cells blank? This is a LIVE Bloomberg workbook — it has no saved data until its first refresh. Open it in desktop Excel on your Bloomberg terminal PC (add-in logged in), then Bloomberg ribbon ▸ Refresh All (or Ctrl+Alt+F9), wait a few minutes, and save. See README.
A2: Blue cells are inputs. Row order here = row order on every data/metric/dashboard sheet. If you add names, insert rows INSIDE the list on this sheet and copy formulas down on the sector sheets.
A4: Software (99 tickers) | D4: Semiconductors (139 tickers)
A5: GOOG US Equity | D5: STM US Equity
A6: MSFT US Equity | D6: ARM US Equity
A7: ORCL US Equity | D7: 1347 HK Equity
A8: AMD US Equity | D8: 981 HK Equity
A9: SAP GY Equity | D9: TSM US Equity
A10: ARM US Equity | D10: UMC US Equity
A11: CRM US Equity | D11: 000660 KS Equity
A12: SHOP US Equity | D12: SIMO US Equity
A13: PANW US Equity | D13: 005930 KS Equity
A14: CRWD US Equity | D14: 285A JP Equity
A15: INTU US Equity | D15: PSTG US Equity
... A103: SPT US Equity | D103: 2313 TT Equity
D104: 3189 TT Equity
A105: =COUNTA(A5:A103)&" tickers" | D105: AMAT US Equity
D106: 3711 TT Equity
D107: TXN US Equity
D108: 6799 TT Equity
D109: NVDA US Equity
D110: 1560 TT Equity
D111: AVGO US Equity
D112: MSFT US Equity
D113: AMZN US Equity
D114: 3443 TT Equity
D115: 6515 TT Equity
D116: 2360 TT Equity
D117: GOOG US Equity
... D143: 3680 TT Equity
D145: =COUNTA(D5:D143)&" tickers"

Sheet SW Dashboard
A1: Software — Earnings Comp Dashboard (latest reported quarter) | H1: ⚠ Cells blank? This is a LIVE Bloomberg workbook — it has no saved data until its first refresh. Open it in desktop Excel on your Bloomberg terminal PC (add-in logged in), then Bloomberg ribbon ▸ Refresh All (or Ctrl+Alt+F9), wait a few minutes, and save. See README.
A2: USD mm unless noted. Every row reads the same-numbered row on the data/metric sheets. FPO 0 = each company's own latest reported quarter. Estimate-based columns note (Est).
A4: Ticker | B4: Latest Rpt Qtr | C4: Revenue LQ (USD mm) | D4: Rev YoY % | E4: Rev YoY % (prior qtr) | F4: Accel / (Decel) (pp) | G4: Rev QoQ % | H4: $ Added QoQ (mm) | I4: $ Added YoY (mm) | J4: Next Qtr YoY % (Est) | K4: Op Margin % | L4: OpM Δ YoY (bps) | M4: Op Inc YoY % | N4: Incr OpM % (Op Leverage) | O4: Op Lev (x) | P4: FCF Margin LTM % | Q4: FCF Margin Δ YoY (bps) | R4: NTM Rev Rev Δ1M % | S4: NTM Rev Rev Δ3M % | T4: NTM Rev Rev Δ6M % | U4: NTM EPS Rev Δ1M % | V4: NTM EPS Rev Δ3M % | W4: NTM EPS Rev Δ6M % | X4: Rank: Rev YoY | Y4: Rank: NTM Rev Δ3M
A5: Peer Median | C5: =IFERROR(MEDIAN(C8:C106),"") | D5: =IFERROR(MEDIAN(D8:D106),"") | E5: =IFERROR(MEDIAN(E8:E106),"") | F5: =IFERROR(MEDIAN(F8:F106),"") | G5: =IFERROR(MEDIAN(G8:G106),"") | H5: =IFERROR(MEDIAN(H8:H106),"") | I5: =IFERROR(MEDIAN(I8:I106),"") | J5: =IFERROR(MEDIAN(J8:J106),"") | ... W5: =IFERROR(MEDIAN(W8:W106),"")
A6: Top Quartile (75th) | C6: =IFERROR(QUARTILE(C8:C106,3),"") | D6: =IFERROR(QUARTILE(D8:D106,3),"") | E6: =IFERROR(QUARTILE(E8:E106,3),"") | F6: =IFERROR(QUARTILE(F8:F106,3),"") | G6: =IFERROR(QUARTILE(G8:G106,3),"") | H6: =IFERROR(QUARTILE(H8:H106,3),"") | I6: =IFERROR(QUARTILE(I8:I106,3),"") | J6: =IFERROR(QUARTILE(J8:J106,3),"") | ... W6: =IFERROR(QUARTILE(W8:W106,3),"")
A7: Bottom Quartile (25th) | C7: =IFERROR(QUARTILE(C8:C106,1),"") | D7: =IFERROR(QUARTILE(D8:D106,1),"") | E7: =IFERROR(QUARTILE(E8:E106,1),"") | F7: =IFERROR(QUARTILE(F8:F106,1),"") | G7: =IFERROR(QUARTILE(G8:G106,1),"") | H7: =IFERROR(QUARTILE(H8:H106,1),"") | I7: =IFERROR(QUARTILE(I8:I106,1),"") | J7: =IFERROR(QUARTILE(J8:J106,1),"") | ... W7: =IFERROR(QUARTILE(W8:W106,1),"")
A8: ='SW Rev'!$A5 | B8: ='SW Rev'!$B5 | C8: =IF(ISNUMBER('SW Rev'!P5),'SW Rev'!P5,"") | D8: ='SW Metrics'!L108 | E8: ='SW Metrics'!K108 | F8: =IF(OR(D8="",E8=""),"",D8-E8) | G8: ='SW Metrics'!L210 | H8: ='SW Metrics'!L414 | I8: ='SW Metrics'!L312 | J8: ='SW Metrics'!M108 | K8: ='SW Metrics'!L516 | L8: ='SW Metrics'!L618 | M8: ='SW Metrics'!L720 | N8: ='SW Metrics'!L822 | O8: =IFERROR(IF(AND(N(D8)>0,N(M8)>0),M8/D8,""),"") | P8: ='SW Metrics'!L924 | Q8: ='SW Metrics'!L1026 | R8: ='SW Revisions'!G6 | S8: ='SW Revisions'!H6 | T8: ='SW Revisions'!I6 | U8: ='SW Revisions'!O6 | V8: ='SW Revisions'!P6 | W8: ='SW Revisions'!Q6 | X8: =IFERROR(RANK(D8,D$8:D$106),"") | Y8: =IFERROR(RANK(S8,S$8:S$106),"")
A9: ='SW Rev'!$A6 | B9: ='SW Rev'!$B6 | C9: =IF(ISNUMBER('SW Rev'!P6),'SW Rev'!P6,"") | D9: ='SW Metrics'!L109 | E9: ='SW Metrics'!K109 | F9: =IF(OR(D9="",E9=""),"",D9-E9) | G9: ='SW Metrics'!L211 | H9: ='SW Metrics'!L415 | I9: ='SW Metrics'!L313 | J9: ='SW Metrics'!M109 | K9: ='SW Metrics'!L517 | L9: ='SW Metrics'!L619 | M9: ='SW Metrics'!L721 | N9: ='SW Metrics'!L823 | O9: =IFERROR(IF(AND(N(D9)>0,N(M9)>0),M9/D9,""),"") | P9: ='SW Metrics'!L925 | Q9: ='SW Metrics'!L1027 | R9: ='SW Revisions'!G7 | S9: ='SW Revisions'!H7 | T9: ='SW Revisions'!I7 | U9: ='SW Revisions'!O7 | V9: ='SW Revisions'!P7 | W9: ='SW Revisions'!Q7 | X9: =IFERROR(RANK(D9,D$8:D$106),"") | Y9: =IFERROR(RANK(S9,S$8:S$106),"")
A10: ='SW Rev'!$A7 | B10: ='SW Rev'!$B7 | C10: =IF(ISNUMBER('SW Rev'!P7),'SW Rev'!P7,"") | D10: ='SW Metrics'!L110 | E10: ='SW Metrics'!K110 | F10: =IF(OR(D10="",E10=""),"",D10-E10) | G10: ='SW Metrics'!L212 | H10: ='SW Metrics'!L416 | I10: ='SW Metrics'!L314 | J10: ='SW Metrics'!M110 | K10: ='SW Metrics'!L518 | L10: ='SW Metrics'!L620 | M10: ='SW Metrics'!L722 | N10: ='SW Metrics'!L824 | O10: =IFERROR(IF(AND(N(D10)>0,N(M10)>0),M10/D10,""),"") | P10: ='SW Metrics'!L926 | Q10: ='SW Metrics'!L1028 | R10: ='SW Revisions'!G8 | S10: ='SW Revisions'!H8 | T10: ='SW Revisions'!I8 | U10: ='SW Revisions'!O8 | V10: ='SW Revisions'!P8 | W10: ='SW Revisions'!Q8 | X10: =IFERROR(RANK(D10,D$8:D$106),"") | Y10: =IFERROR(RANK(S10,S$8:S$106),"")
A11: ='SW Rev'!$A8 | B11: ='SW Rev'!$B8 | C11: =IF(ISNUMBER('SW Rev'!P8),'SW Rev'!P8,"") | D11: ='SW Metrics'!L111 | E11: ='SW Metrics'!K111 | F11: =IF(OR(D11="",E11=""),"",D11-E11) | G11: ='SW Metrics'!L213 | H11: ='SW Metrics'!L417 | I11: ='SW Metrics'!L315 | J11: ='SW Metrics'!M111 | K11: ='SW Metrics'!L519 | L11: ='SW Metrics'!L621 | M11: ='SW Metrics'!L723 | N11: ='SW Metrics'!L825 | O11: =IFERROR(IF(AND(N(D11)>0,N(M11)>0),M11/D11,""),"") | P11: ='SW Metrics'!L927 | Q11: ='SW Metrics'!L1029 | R11: ='SW Revisions'!G9 | S11: ='SW Revisions'!H9 | T11: ='SW Revisions'!I9 | U11: ='SW Revisions'!O9 | V11: ='SW Revisions'!P9 | W11: ='SW Revisions'!Q9 | X11: =IFERROR(RANK(D11,D$8:D$106),"") | Y11: =IFERROR(RANK(S11,S$8:S$106),"")
A12: ='SW Rev'!$A9 | B12: ='SW Rev'!$B9 | C12: =IF(ISNUMBER('SW Rev'!P9),'SW Rev'!P9,"") | D12: ='SW Metrics'!L112 | E12: ='SW Metrics'!K112 | F12: =IF(OR(D12="",E12=""),"",D12-E12) | G12: ='SW Metrics'!L214 | H12: ='SW Metrics'!L418 | I12: ='SW Metrics'!L316 | J12: ='SW Metrics'!M112 | K12: ='SW Metrics'!L520 | L12: ='SW Metrics'!L622 | M12: ='SW Metrics'!L724 | N12: ='SW Metrics'!L826 | O12: =IFERROR(IF(AND(N(D12)>0,N(M12)>0),M12/D12,""),"") | P12: ='SW Metrics'!L928 | Q12: ='SW Metrics'!L1030 | R12: ='SW Revisions'!G10 | S12: ='SW Revisions'!H10 | T12: ='SW Revisions'!I10 | U12: ='SW Revisions'!O10 | V12: ='SW Revisions'!P10 | W12: ='SW Revisions'!Q10 | X12: =IFERROR(RANK(D12,D$8:D$106),"") | Y12: =IFERROR(RANK(S12,S$8:S$106),"")
A13: ='SW Rev'!$A10 | B13: ='SW Rev'!$B10 | C13: =IF(ISNUMBER('SW Rev'!P10),'SW Rev'!P10,"") | D13: ='SW Metrics'!L113 | E13: ='SW Metrics'!K113 | F13: =IF(OR(D13="",E13=""),"",D13-E13) | G13: ='SW Metrics'!L215 | H13: ='SW Metrics'!L419 | I13: ='SW Metrics'!L317 | J13: ='SW Metrics'!M113 | K13: ='SW Metrics'!L521 | L13: ='SW Metrics'!L623 | M13: ='SW Metrics'!L725 | N13: ='SW Metrics'!L827 | O13: =IFERROR(IF(AND(N(D13)>0,N(M13)>0),M13/D13,""),"") | P13: ='SW Metrics'!L929 | Q13: ='SW Metrics'!L1031 | R13: ='SW Revisions'!G11 | S13: ='SW Revisions'!H11 | T13: ='SW Revisions'!I11 | U13: ='SW Revisions'!O11 | V13: ='SW Revisions'!P11 | W13: ='SW Revisions'!Q11 | X13: =IFERROR(RANK(D13,D$8:D$106),"") | Y13: =IFERROR(RANK(S13,S$8:S$106),"")
A14: ='SW Rev'!$A11 | B14: ='SW Rev'!$B11 | C14: =IF(ISNUMBER('SW Rev'!P11),'SW Rev'!P11,"") | D14: ='SW Metrics'!L114 | E14: ='SW Metrics'!K114 | F14: =IF(OR(D14="",E14=""),"",D14-E14) | G14: ='SW Metrics'!L216 | H14: ='SW Metrics'!L420 | I14: ='SW Metrics'!L318 | J14: ='SW Metrics'!M114 | K14: ='SW Metrics'!L522 | L14: ='SW Metrics'!L624 | M14: ='SW Metrics'!L726 | N14: ='SW Metrics'!L828 | O14: =IFERROR(IF(AND(N(D14)>0,N(M14)>0),M14/D14,""),"") | P14: ='SW Metrics'!L930 | Q14: ='SW Metrics'!L1032 | R14: ='SW Revisions'!G12 | S14: ='SW Revisions'!H12 | T14: ='SW Revisions'!I12 | U14: ='SW Revisions'!O12 | V14: ='SW Revisions'!P12 | W14: ='SW Revisions'!Q12 | X14: =IFERROR(RANK(D14,D$8:D$106),"") | Y14: =IFERROR(RANK(S14,S$8:S$106),"")
A15: ='SW Rev'!$A12 | B15: ='SW Rev'!$B12 | C15: =IF(ISNUMBER('SW Rev'!P12),'SW Rev'!P12,"") | D15: ='SW Metrics'!L115 | E15: ='SW Metrics'!K115 | F15: =IF(OR(D15="",E15=""),"",D15-E15) | G15: ='SW Metrics'!L217 | H15: ='SW Metrics'!L421 | I15: ='SW Metrics'!L319 | J15: ='SW Metrics'!M115 | K15: ='SW Metrics'!L523 | L15: ='SW Metrics'!L625 | M15: ='SW Metrics'!L727 | N15: ='SW Metrics'!L829 | O15: =IFERROR(IF(AND(N(D15)>0,N(M15)>0),M15/D15,""),"") | P15: ='SW Metrics'!L931 | Q15: ='SW Metrics'!L1033 | R15: ='SW Revisions'!G13 | S15: ='SW Revisions'!H13 | T15: ='SW Revisions'!I13 | U15: ='SW Revisions'!O13 | V15: ='SW Revisions'!P13 | W15: ='SW Revisions'!Q13 | X15: =IFERROR(RANK(D15,D$8:D$106),"") | Y15: =IFERROR(RANK(S15,S$8:S$106),"")
A16: ='SW Rev'!$A13 | B16: ='SW Rev'!$B13 | C16: =IF(ISNUMBER('SW Rev'!P13),'SW Rev'!P13,"") | D16: ='SW Metrics'!L116 | E16: ='SW Metrics'!K116 | F16: =IF(OR(D16="",E16=""),"",D16-E16) | G16: ='SW Metrics'!L218 | H16: ='SW Metrics'!L422 | I16: ='SW Metrics'!L320 | J16: ='SW Metrics'!M116 | K16: ='SW Metrics'!L524 | L16: ='SW Metrics'!L626 | M16: ='SW Metrics'!L728 | N16: ='SW Metrics'!L830 | O16: =IFERROR(IF(AND(N(D16)>0,N(M16)>0),M16/D16,""),"") | P16: ='SW Metrics'!L932 | Q16: ='SW Metrics'!L1034 | R16: ='SW Revisions'!G14 | S16: ='SW Revisions'!H14 | T16: ='SW Revisions'!I14 | U16: ='SW Revisions'!O14 | V16: ='SW Revisions'!P14 | W16: ='SW Revisions'!Q14 | X16: =IFERROR(RANK(D16,D$8:D$106),"") | Y16: =IFERROR(RANK(S16,S$8:S$106),"")
A17: ='SW Rev'!$A14 | B17: ='SW Rev'!$B14 | C17: =IF(ISNUMBER('SW Rev'!P14),'SW Rev'!P14,"") | D17: ='SW Metrics'!L117 | E17: ='SW Metrics'!K117 | F17: =IF(OR(D17="",E17=""),"",D17-E17) | G17: ='SW Metrics'!L219 | H17: ='SW Metrics'!L423 | I17: ='SW Metrics'!L321 | J17: ='SW Metrics'!M117 | K17: ='SW Metrics'!L525 | L17: ='SW Metrics'!L627 | M17: ='SW Metrics'!L729 | N17: ='SW Metrics'!L831 | O17: =IFERROR(IF(AND(N(D17)>0,N(M17)>0),M17/D17,""),"") | P17: ='SW Metrics'!L933 | Q17: ='SW Metrics'!L1035 | R17: ='SW Revisions'!G15 | S17: ='SW Revisions'!H15 | T17: ='SW Revisions'!I15 | U17: ='SW Revisions'!O15 | V17: ='SW Revisions'!P15 | W17: ='SW Revisions'!Q15 | X17: =IFERROR(RANK(D17,D$8:D$106),"") | Y17: =IFERROR(RANK(S17,S$8:S$106),"")
A18: ='SW Rev'!$A15 | B18: ='SW Rev'!$B15 | C18: =IF(ISNUMBER('SW Rev'!P15),'SW Rev'!P15,"") | D18: ='SW Metrics'!L118 | E18: ='SW Metrics'!K118 | F18: =IF(OR(D18="",E18=""),"",D18-E18) | G18: ='SW Metrics'!L220 | H18: ='SW Metrics'!L424 | I18: ='SW Metrics'!L322 | J18: ='SW Metrics'!M118 | K18: ='SW Metrics'!L526 | L18: ='SW Metrics'!L628 | M18: ='SW Metrics'!L730 | N18: ='SW Metrics'!L832 | O18: =IFERROR(IF(AND(N(D18)>0,N(M18)>0),M18/D18,""),"") | P18: ='SW Metrics'!L934 | Q18: ='SW Metrics'!L1036 | R18: ='SW Revisions'!G16 | S18: ='SW Revisions'!H16 | T18: ='SW Revisions'!I16 | U18: ='SW Revisions'!O16 | V18: ='SW Revisions'!P16 | W18: ='SW Revisions'!Q16 | X18: =IFERROR(RANK(D18,D$8:D$106),"") | Y18: =IFERROR(RANK(S18,S$8:S$106),"")
A19: ='SW Rev'!$A16 | B19: ='SW Rev'!$B16 | C19: =IF(ISNUMBER('SW Rev'!P16),'SW Rev'!P16,"") | D19: ='SW Metrics'!L119 | E19: ='SW Metrics'!K119 | F19: =IF(OR(D19="",E19=""),"",D19-E19) | G19: ='SW Metrics'!L221 | H19: ='SW Metrics'!L425 | I19: ='SW Metrics'!L323 | J19: ='SW Metrics'!M119 | K19: ='SW Metrics'!L527 | L19: ='SW Metrics'!L629 | M19: ='SW Metrics'!L731 | N19: ='SW Metrics'!L833 | O19: =IFERROR(IF(AND(N(D19)>0,N(M19)>0),M19/D19,""),"") | P19: ='SW Metrics'!L935 | Q19: ='SW Metrics'!L1037 | R19: ='SW Revisions'!G17 | S19: ='SW Revisions'!H17 | T19: ='SW Revisions'!I17 | U19: ='SW Revisions'!O17 | V19: ='SW Revisions'!P17 | W19: ='SW Revisions'!Q17 | X19: =IFERROR(RANK(D19,D$8:D$106),"") | Y19: =IFERROR(RANK(S19,S$8:S$106),"")
... A106: ='SW Rev'!$A103 | B106: ='SW Rev'!$B103 | C106: =IF(ISNUMBER('SW Rev'!P103),'SW Rev'!P103,"") | D106: ='SW Metrics'!L206 | E106: ='SW Metrics'!K206 | F106: =IF(OR(D106="",E106=""),"",D106-E106) | G106: ='SW Metrics'!L308 | H106: ='SW Metrics'!L512 | I106: ='SW Metrics'!L410 | J106: ='SW Metrics'!M206 | K106: ='SW Metrics'!L614 | L106: ='SW Metrics'!L716 | M106: ='SW Metrics'!L818 | N106: ='SW Metrics'!L920 | O106: =IFERROR(IF(AND(N(D106)>0,N(M106)>0),M106/D106,""),"") | P106: ='SW Metrics'!L1022 | Q106: ='SW Metrics'!L1124 | R106: ='SW Revisions'!G104 | S106: ='SW Revisions'!H104 | T106: ='SW Revisions'!I104 | U106: ='SW Revisions'!O104 | V106: ='SW Revisions'!P104 | W106: ='SW Revisions'!Q104 | X106: =IFERROR(RANK(D106,D$8:D$106),"") | Y106: =IFERROR(RANK(S106,S$8:S$106),"")

Sheet SW Focus
A1: Software — Single-Name vs Peers | H1: ⚠ Cells blank? This is a LIVE Bloomberg workbook — it has no saved data until its first refresh. Open it in desktop Excel on your Bloomberg terminal PC (add-in logged in), then Bloomberg ribbon ▸ Refresh All (or Ctrl+Alt+F9), wait a few minutes, and save. See README.
A2: Type any ticker from the Tickers sheet into the yellow cell. Each metric shows the company, the peer-set median (computed over the full list, selected name included), and the gap. Columns aligned by FPO (company's own fiscal quarters).
A4: Company (edit): | B4: ZM US Equity | C4: =IFERROR("Latest reported qtr: "&INDEX('SW Rev'!$B$5:$B$103,MATCH($B$4,'SW Rev'!$A$5:$A$103,0)),"⚠ ticker not found in Tickers list")
A6: Metric | B6: Series | C6: FPO -9 | D6: FPO -8 | E6: FPO -7 | F6: FPO -6 | G6: FPO -5 | H6: FPO -4 | I6: FPO -3 | J6: FPO -2 | K6: FPO -1 | L6: FPO 0 (latest rpt) | M6: FPO +1E | N6: FPO +2E
A7: Revenue (USD mm) | B7: Company | C7: =IFERROR(INDEX('SW Metrics'!$C$6:$C$104,MATCH($B$4,'SW Metrics'!$A$6:$A$104,0)),"") | D7: =IFERROR(INDEX('SW Metrics'!$D$6:$D$104,MATCH($B$4,'SW Metrics'!$A$6:$A$104,0)),"") | E7: =IFERROR(INDEX('SW Metrics'!$E$6:$E$104,MATCH($B$4,'SW Metrics'!$A$6:$A$104,0)),"") | F7: =IFERROR(INDEX('SW Metrics'!$F$6:$F$104,MATCH($B$4,'SW Metrics'!$A$6:$A$104,0)),"") | G7: =IFERROR(INDEX('SW Metrics'!$G$6:$G$104,MATCH($B$4,'SW Metrics'!$A$6:$A$104,0)),"") | H7: =IFERROR(INDEX('SW Metrics'!$H$6:$H$104,MATCH($B$4,'SW Metrics'!$A$6:$A$104,0)),"") | I7: =IFERROR(INDEX('SW Metrics'!$I$6:$I$104,MATCH($B$4,'SW Metrics'!$A$6:$A$104,0)),"") | J7: =IFERROR(INDEX('SW Metrics'!$J$6:$J$104,MATCH($B$4,'SW Metrics'!$A$6:$A$104,0)),"") | K7: =IFERROR(INDEX('SW Metrics'!$K$6:$K$104,MATCH($B$4,'SW Metrics'!$A$6:$A$104,0)),"") | L7: =IFERROR(INDEX('SW Metrics'!$L$6:$L$104,MATCH($B$4,'SW Metrics'!$A$6:$A$104,0)),"") | M7: =IFERROR(INDEX('SW Metrics'!$M$6:$M$104,MATCH($B$4,'SW Metrics'!$A$6:$A$104,0)),"") | N7: =IFERROR(INDEX('SW Metrics'!$N$6:$N$104,MATCH($B$4,'SW Metrics'!$A$6:$A$104,0)),"")
B8: Peer median | C8: =IFERROR(MEDIAN('SW Metrics'!$C$6:$C$104),"") | D8: =IFERROR(MEDIAN('SW Metrics'!$D$6:$D$104),"") | E8: =IFERROR(MEDIAN('SW Metrics'!$E$6:$E$104),"") | F8: =IFERROR(MEDIAN('SW Metrics'!$F$6:$F$104),"") | G8: =IFERROR(MEDIAN('SW Metrics'!$G$6:$G$104),"") | H8: =IFERROR(MEDIAN('SW Metrics'!$H$6:$H$104),"") | I8: =IFERROR(MEDIAN('SW Metrics'!$I$6:$I$104),"") | J8: =IFERROR(MEDIAN('SW Metrics'!$J$6:$J$104),"") | K8: =IFERROR(MEDIAN('SW Metrics'!$K$6:$K$104),"") | L8: =IFERROR(MEDIAN('SW Metrics'!$L$6:$L$104),"") | M8: =IFERROR(MEDIAN('SW Metrics'!$M$6:$M$104),"") | N8: =IFERROR(MEDIAN('SW Metrics'!$N$6:$N$104),"")
B9: vs median | C9: =IF(OR(C7="",C8=""),"",C7-C8) | D9: =IF(OR(D7="",D8=""),"",D7-D8) | E9: =IF(OR(E7="",E8=""),"",E7-E8) | F9: =IF(OR(F7="",F8=""),"",F7-F8) | G9: =IF(OR(G7="",G8=""),"",G7-G8) | H9: =IF(OR(H7="",H8=""),"",H7-H8) | I9: =IF(OR(I7="",I8=""),"",I7-I8) | J9: =IF(OR(J7="",J8=""),"",J7-J8) | ... N9: =IF(OR(N7="",N8=""),"",N7-N8)
A11: Revenue growth YoY % | B11: Company | C11: =IFERROR(INDEX('SW Metrics'!$C$108:$C$206,MATCH($B$4,'SW Metrics'!$A$108:$A$206,0)),"") | D11: =IFERROR(INDEX('SW Metrics'!$D$108:$D$206,MATCH($B$4,'SW Metrics'!$A$108:$A$206,0)),"") | E11: =IFERROR(INDEX('SW Metrics'!$E$108:$E$206,MATCH($B$4,'SW Metrics'!$A$108:$A$206,0)),"") | F11: =IFERROR(INDEX('SW Metrics'!$F$108:$F$206,MATCH($B$4,'SW Metrics'!$A$108:$A$206,0)),"") | G11: =IFERROR(INDEX('SW Metrics'!$G$108:$G$206,MATCH($B$4,'SW Metrics'!$A$108:$A$206,0)),"") | H11: =IFERROR(INDEX('SW Metrics'!$H$108:$H$206,MATCH($B$4,'SW Metrics'!$A$108:$A$206,0)),"") | I11: =IFERROR(INDEX('SW Metrics'!$I$108:$I$206,MATCH($B$4,'SW Metrics'!$A$108:$A$206,0)),"") | J11: =IFERROR(INDEX('SW Metrics'!$J$108:$J$206,MATCH($B$4,'SW Metrics'!$A$108:$A$206,0)),"") | K11: =IFERROR(INDEX('SW Metrics'!$K$108:$K$206,MATCH($B$4,'SW Metrics'!$A$108:$A$206,0)),"") | L11: =IFERROR(INDEX('SW Metrics'!$L$108:$L$206,MATCH($B$4,'SW Metrics'!$A$108:$A$206,0)),"") | M11: =IFERROR(INDEX('SW Metrics'!$M$108:$M$206,MATCH($B$4,'SW Metrics'!$A$108:$A$206,0)),"") | N11: =IFERROR(INDEX('SW Metrics'!$N$108:$N$206,MATCH($B$4,'SW Metrics'!$A$108:$A$206,0)),"")
B12: Peer median | C12: =IFERROR(MEDIAN('SW Metrics'!$C$108:$C$206),"") | D12: =IFERROR(MEDIAN('SW Metrics'!$D$108:$D$206),"") | E12: =IFERROR(MEDIAN('SW Metrics'!$E$108:$E$206),"") | F12: =IFERROR(MEDIAN('SW Metrics'!$F$108:$F$206),"") | G12: =IFERROR(MEDIAN('SW Metrics'!$G$108:$G$206),"") | H12: =IFERROR(MEDIAN('SW Metrics'!$H$108:$H$206),"") | I12: =IFERROR(MEDIAN('SW Metrics'!$I$108:$I$206),"") | J12: =IFERROR(MEDIAN('SW Metrics'!$J$108:$J$206),"") | K12: =IFERROR(MEDIAN('SW Metrics'!$K$108:$K$206),"") | L12: =IFERROR(MEDIAN('SW Metrics'!$L$108:$L$206),"") | M12: =IFERROR(MEDIAN('SW Metrics'!$M$108:$M$206),"") | N12: =IFERROR(MEDIAN('SW Metrics'!$N$108:$N$206),"")
B13: vs median | C13: =IF(OR(C11="",C12=""),"",C11-C12) | D13: =IF(OR(D11="",D12=""),"",D11-D12) | E13: =IF(OR(E11="",E12=""),"",E11-E12) | F13: =IF(OR(F11="",F12=""),"",F11-F12) | G13: =IF(OR(G11="",G12=""),"",G11-G12) | H13: =IF(OR(H11="",H12=""),"",H11-H12) | I13: =IF(OR(I11="",I12=""),"",I11-I12) | J13: =IF(OR(J11="",J12=""),"",J11-J12) | ... N13: =IF(OR(N11="",N12=""),"",N11-N12)
A15: Revenue growth QoQ % | B15: Company | C15: =IFERROR(INDEX('SW Metrics'!$C$210:$C$308,MATCH($B$4,'SW Metrics'!$A$210:$A$308,0)),"") | D15: =IFERROR(INDEX('SW Metrics'!$D$210:$D$308,MATCH($B$4,'SW Metrics'!$A$210:$A$308,0)),"") | E15: =IFERROR(INDEX('SW Metrics'!$E$210:$E$308,MATCH($B$4,'SW Metrics'!$A$210:$A$308,0)),"") | F15: =IFERROR(INDEX('SW Metrics'!$F$210:$F$308,MATCH($B$4,'SW Metrics'!$A$210:$A$308,0)),"") | G15: =IFERROR(INDEX('SW Metrics'!$G$210:$G$308,MATCH($B$4,'SW Metrics'!$A$210:$A$308,0)),"") | H15: =IFERROR(INDEX('SW Metrics'!$H$210:$H$308,MATCH($B$4,'SW Metrics'!$A$210:$A$308,0)),"") | I15: =IFERROR(INDEX('SW Metrics'!$I$210:$I$308,MATCH($B$4,'SW Metrics'!$A$210:$A$308,0)),"") | J15: =IFERROR(INDEX('SW Metrics'!$J$210:$J$308,MATCH($B$4,'SW Metrics'!$A$210:$A$308,0)),"") | K15: =IFERROR(INDEX('SW Metrics'!$K$210:$K$308,MATCH($B$4,'SW Metrics'!$A$210:$A$308,0)),"") | L15: =IFERROR(INDEX('SW Metrics'!$L$210:$L$308,MATCH($B$4,'SW Metrics'!$A$210:$A$308,0)),"") | M15: =IFERROR(INDEX('SW Metrics'!$M$210:$M$308,MATCH($B$4,'SW Metrics'!$A$210:$A$308,0)),"") | N15: =IFERROR(INDEX('SW Metrics'!$N$210:$N$308,MATCH($B$4,'SW Metrics'!$A$210:$A$308,0)),"")
B16: Peer median | C16: =IFERROR(MEDIAN('SW Metrics'!$C$210:$C$308),"") | D16: =IFERROR(MEDIAN('SW Metrics'!$D$210:$D$308),"") | E16: =IFERROR(MEDIAN('SW Metrics'!$E$210:$E$308),"") | F16: =IFERROR(MEDIAN('SW Metrics'!$F$210:$F$308),"") | G16: =IFERROR(MEDIAN('SW Metrics'!$G$210:$G$308),"") | H16: =IFERROR(MEDIAN('SW Metrics'!$H$210:$H$308),"") | I16: =IFERROR(MEDIAN('SW Metrics'!$I$210:$I$308),"") | J16: =IFERROR(MEDIAN('SW Metrics'!$J$210:$J$308),"") | K16: =IFERROR(MEDIAN('SW Metrics'!$K$210:$K$308),"") | L16: =IFERROR(MEDIAN('SW Metrics'!$L$210:$L$308),"") | M16: =IFERROR(MEDIAN('SW Metrics'!$M$210:$M$308),"") | N16: =IFERROR(MEDIAN('SW Metrics'!$N$210:$N$308),"")
B17: vs median | C17: =IF(OR(C15="",C16=""),"",C15-C16) | D17: =IF(OR(D15="",D16=""),"",D15-D16) | E17: =IF(OR(E15="",E16=""),"",E15-E16) | F17: =IF(OR(F15="",F16=""),"",F15-F16) | G17: =IF(OR(G15="",G16=""),"",G15-G16) | H17: =IF(OR(H15="",H16=""),"",H15-H16) | I17: =IF(OR(I15="",I16=""),"",I15-I16) | J17: =IF(OR(J15="",J16=""),"",J15-J16) | ... N17: =IF(OR(N15="",N16=""),"",N15-N16)
A19: $ Added YoY (USD mm) | B19: Company | C19: =IFERROR(INDEX('SW Metrics'!$C$312:$C$410,MATCH($B$4,'SW Metrics'!$A$312:$A$410,0)),"") | D19: =IFERROR(INDEX('SW Metrics'!$D$312:$D$410,MATCH($B$4,'SW Metrics'!$A$312:$A$410,0)),"") | E19: =IFERROR(INDEX('SW Metrics'!$E$312:$E$410,MATCH($B$4,'SW Metrics'!$A$312:$A$410,0)),"") | F19: =IFERROR(INDEX('SW Metrics'!$F$312:$F$410,MATCH($B$4,'SW Metrics'!$A$312:$A$410,0)),"") | G19: =IFERROR(INDEX('SW Metrics'!$G$312:$G$410,MATCH($B$4,'SW Metrics'!$A$312:$A$410,0)),"") | H19: =IFERROR(INDEX('SW Metrics'!$H$312:$H$410,MATCH($B$4,'SW Metrics'!$A$312:$A$410,0)),"") | I19: =IFERROR(INDEX('SW Metrics'!$I$312:$I$410,MATCH($B$4,'SW Metrics'!$A$312:$A$410,0)),"") | J19: =IFERROR(INDEX('SW Metrics'!$J$312:$J$410,MATCH($B$4,'SW Metrics'!$A$312:$A$410,0)),"") | K19: =IFERROR(INDEX('SW Metrics'!$K$312:$K$410,MATCH($B$4,'SW Metrics'!$A$312:$A$410,0)),"") | L19: =IFERROR(INDEX('SW Metrics'!$L$312:$L$410,MATCH($B$4,'SW Metrics'!$A$312:$A$410,0)),"") | M19: =IFERROR(INDEX('SW Metrics'!$M$312:$M$410,MATCH($B$4,'SW Metrics'!$A$312:$A$410,0)),"") | N19: =IFERROR(INDEX('SW Metrics'!$N$312:$N$410,MATCH($B$4,'SW Metrics'!$A$312:$A$410,0)),"")
B20: Peer median | C20: =IFERROR(MEDIAN('SW Metrics'!$C$312:$C$410),"") | D20: =IFERROR(MEDIAN('SW Metrics'!$D$312:$D$410),"") | E20: =IFERROR(MEDIAN('SW Metrics'!$E$312:$E$410),"") | F20: =IFERROR(MEDIAN('SW Metrics'!$F$312:$F$410),"") | G20: =IFERROR(MEDIAN('SW Metrics'!$G$312:$G$410),"") | H20: =IFERROR(MEDIAN('SW Metrics'!$H$312:$H$410),"") | I20: =IFERROR(MEDIAN('SW Metrics'!$I$312:$I$410),"") | J20: =IFERROR(MEDIAN('SW Metrics'!$J$312:$J$410),"") | K20: =IFERROR(MEDIAN('SW Metrics'!$K$312:$K$410),"") | L20: =IFERROR(MEDIAN('SW Metrics'!$L$312:$L$410),"") | M20: =IFERROR(MEDIAN('SW Metrics'!$M$312:$M$410),"") | N20: =IFERROR(MEDIAN('SW Metrics'!$N$312:$N$410),"")
B21: vs median | C21: =IF(OR(C19="",C20=""),"",C19-C20) | D21: =IF(OR(D19="",D20=""),"",D19-D20) | E21: =IF(OR(E19="",E20=""),"",E19-E20) | F21: =IF(OR(F19="",F20=""),"",F19-F20) | G21: =IF(OR(G19="",G20=""),"",G19-G20) | H21: =IF(OR(H19="",H20=""),"",H19-H20) | I21: =IF(OR(I19="",I20=""),"",I19-I20) | J21: =IF(OR(J19="",J20=""),"",J19-J20) | ... N21: =IF(OR(N19="",N20=""),"",N19-N20)
A23: $ Added QoQ (USD mm) | B23: Company | C23: =IFERROR(INDEX('SW Metrics'!$C$414:$C$512,MATCH($B$4,'SW Metrics'!$A$414:$A$512,0)),"") | D23: =IFERROR(INDEX('SW Metrics'!$D$414:$D$512,MATCH($B$4,'SW Metrics'!$A$414:$A$512,0)),"") | E23: =IFERROR(INDEX('SW Metrics'!$E$414:$E$512,MATCH($B$4,'SW Metrics'!$A$414:$A$512,0)),"") | F23: =IFERROR(INDEX('SW Metrics'!$F$414:$F$512,MATCH($B$4,'SW Metrics'!$A$414:$A$512,0)),"") | G23: =IFERROR(INDEX('SW Metrics'!$G$414:$G$512,MATCH($B$4,'SW Metrics'!$A$414:$A$512,0)),"") | H23: =IFERROR(INDEX('SW Metrics'!$H$414:$H$512,MATCH($B$4,'SW Metrics'!$A$414:$A$512,0)),"") | I23: =IFERROR(INDEX('SW Metrics'!$I$414:$I$512,MATCH($B$4,'SW Metrics'!$A$414:$A$512,0)),"") | J23: =IFERROR(INDEX('SW Metrics'!$J$414:$J$512,MATCH($B$4,'SW Metrics'!$A$414:$A$512,0)),"") | K23: =IFERROR(INDEX('SW Metrics'!$K$414:$K$512,MATCH($B$4,'SW Metrics'!$A$414:$A$512,0)),"") | L23: =IFERROR(INDEX('SW Metrics'!$L$414:$L$512,MATCH($B$4,'SW Metrics'!$A$414:$A$512,0)),"") | M23: =IFERROR(INDEX('SW Metrics'!$M$414:$M$512,MATCH($B$4,'SW Metrics'!$A$414:$A$512,0)),"") | N23: =IFERROR(INDEX('SW Metrics'!$N$414:$N$512,MATCH($B$4,'SW Metrics'!$A$414:$A$512,0)),"")
B24: Peer median | C24: =IFERROR(MEDIAN('SW Metrics'!$C$414:$C$512),"") | D24: =IFERROR(MEDIAN('SW Metrics'!$D$414:$D$512),"") | E24: =IFERROR(MEDIAN('SW Metrics'!$E$414:$E$512),"") | F24: =IFERROR(MEDIAN('SW Metrics'!$F$414:$F$512),"") | G24: =IFERROR(MEDIAN('SW Metrics'!$G$414:$G$512),"") | H24: =IFERROR(MEDIAN('SW Metrics'!$H$414:$H$512),"") | I24: =IFERROR(MEDIAN('SW Metrics'!$I$414:$I$512),"") | J24: =IFERROR(MEDIAN('SW Metrics'!$J$414:$J$512),"") | K24: =IFERROR(MEDIAN('SW Metrics'!$K$414:$K$512),"") | L24: =IFERROR(MEDIAN('SW Metrics'!$L$414:$L$512),"") | M24: =IFERROR(MEDIAN('SW Metrics'!$M$414:$M$512),"") | N24: =IFERROR(MEDIAN('SW Metrics'!$N$414:$N$512),"")
B25: vs median | C25: =IF(OR(C23="",C24=""),"",C23-C24) | D25: =IF(OR(D23="",D24=""),"",D23-D24) | E25: =IF(OR(E23="",E24=""),"",E23-E24) | F25: =IF(OR(F23="",F24=""),"",F23-F24) | G25: =IF(OR(G23="",G24=""),"",G23-G24) | H25: =IF(OR(H23="",H24=""),"",H23-H24) | I25: =IF(OR(I23="",I24=""),"",I23-I24) | J25: =IF(OR(J23="",J24=""),"",J23-J24) | ... N25: =IF(OR(N23="",N24=""),"",N23-N24)
A27: Op margin % | B27: Company | C27: =IFERROR(INDEX('SW Metrics'!$C$516:$C$614,MATCH($B$4,'SW Metrics'!$A$516:$A$614,0)),"") | D27: =IFERROR(INDEX('SW Metrics'!$D$516:$D$614,MATCH($B$4,'SW Metrics'!$A$516:$A$614,0)),"") | E27: =IFERROR(INDEX('SW Metrics'!$E$516:$E$614,MATCH($B$4,'SW Metrics'!$A$516:$A$614,0)),"") | F27: =IFERROR(INDEX('SW Metrics'!$F$516:$F$614,MATCH($B$4,'SW Metrics'!$A$516:$A$614,0)),"") | G27: =IFERROR(INDEX('SW Metrics'!$G$516:$G$614,MATCH($B$4,'SW Metrics'!$A$516:$A$614,0)),"") | H27: =IFERROR(INDEX('SW Metrics'!$H$516:$H$614,MATCH($B$4,'SW Metrics'!$A$516:$A$614,0)),"") | I27: =IFERROR(INDEX('SW Metrics'!$I$516:$I$614,MATCH($B$4,'SW Metrics'!$A$516:$A$614,0)),"") | J27: =IFERROR(INDEX('SW Metrics'!$J$516:$J$614,MATCH($B$4,'SW Metrics'!$A$516:$A$614,0)),"") | K27: =IFERROR(INDEX('SW Metrics'!$K$516:$K$614,MATCH($B$4,'SW Metrics'!$A$516:$A$614,0)),"") | L27: =IFERROR(INDEX('SW Metrics'!$L$516:$L$614,MATCH($B$4,'SW Metrics'!$A$516:$A$614,0)),"") | M27: =IFERROR(INDEX('SW Metrics'!$M$516:$M$614,MATCH($B$4,'SW Metrics'!$A$516:$A$614,0)),"") | N27: =IFERROR(INDEX('SW Metrics'!$N$516:$N$614,MATCH($B$4,'SW Metrics'!$A$516:$A$614,0)),"")
B28: Peer median | C28: =IFERROR(MEDIAN('SW Metrics'!$C$516:$C$614),"") | D28: =IFERROR(MEDIAN('SW Metrics'!$D$516:$D$614),"") | E28: =IFERROR(MEDIAN('SW Metrics'!$E$516:$E$614),"") | F28: =IFERROR(MEDIAN('SW Metrics'!$F$516:$F$614),"") | G28: =IFERROR(MEDIAN('SW Metrics'!$G$516:$G$614),"") | H28: =IFERROR(MEDIAN('SW Metrics'!$H$516:$H$614),"") | I28: =IFERROR(MEDIAN('SW Metrics'!$I$516:$I$614),"") | J28: =IFERROR(MEDIAN('SW Metrics'!$J$516:$J$614),"") | K28: =IFERROR(MEDIAN('SW Metrics'!$K$516:$K$614),"") | L28: =IFERROR(MEDIAN('SW Metrics'!$L$516:$L$614),"") | M28: =IFERROR(MEDIAN('SW Metrics'!$M$516:$M$614),"") | N28: =IFERROR(MEDIAN('SW Metrics'!$N$516:$N$614),"")
B29: vs median | C29: =IF(OR(C27="",C28=""),"",C27-C28) | D29: =IF(OR(D27="",D28=""),"",D27-D28) | E29: =IF(OR(E27="",E28=""),"",E27-E28) | F29: =IF(OR(F27="",F28=""),"",F27-F28) | G29: =IF(OR(G27="",G28=""),"",G27-G28) | H29: =IF(OR(H27="",H28=""),"",H27-H28) | I29: =IF(OR(I27="",I28=""),"",I27-I28) | J29: =IF(OR(J27="",J28=""),"",J27-J28) | ... N29: =IF(OR(N27="",N28=""),"",N27-N28)
A31: Op margin Δ YoY (bps) | B31: Company | C31: =IFERROR(INDEX('SW Metrics'!$C$618:$C$716,MATCH($B$4,'SW Metrics'!$A$618:$A$716,0)),"") | D31: =IFERROR(INDEX('SW Metrics'!$D$618:$D$716,MATCH($B$4,'SW Metrics'!$A$618:$A$716,0)),"") | E31: =IFERROR(INDEX('SW Metrics'!$E$618:$E$716,MATCH($B$4,'SW Metrics'!$A$618:$A$716,0)),"") | F31: =IFERROR(INDEX('SW Metrics'!$F$618:$F$716,MATCH($B$4,'SW Metrics'!$A$618:$A$716,0)),"") | G31: =IFERROR(INDEX('SW Metrics'!$G$618:$G$716,MATCH($B$4,'SW Metrics'!$A$618:$A$716,0)),"") | H31: =IFERROR(INDEX('SW Metrics'!$H$618:$H$716,MATCH($B$4,'SW Metrics'!$A$618:$A$716,0)),"") | I31: =IFERROR(INDEX('SW Metrics'!$I$618:$I$716,MATCH($B$4,'SW Metrics'!$A$618:$A$716,0)),"") | J31: =IFERROR(INDEX('SW Metrics'!$J$618:$J$716,MATCH($B$4,'SW Metrics'!$A$618:$A$716,0)),"") | K31: =IFERROR(INDEX('SW Metrics'!$K$618:$K$716,MATCH($B$4,'SW Metrics'!$A$618:$A$716,0)),"") | L31: =IFERROR(INDEX('SW Metrics'!$L$618:$L$716,MATCH($B$4,'SW Metrics'!$A$618:$A$716,0)),"") | M31: =IFERROR(INDEX('SW Metrics'!$M$618:$M$716,MATCH($B$4,'SW Metrics'!$A$618:$A$716,0)),"") | N31: =IFERROR(INDEX('SW Metrics'!$N$618:$N$716,MATCH($B$4,'SW Metrics'!$A$618:$A$716,0)),"")
B32: Peer median | C32: =IFERROR(MEDIAN('SW Metrics'!$C$618:$C$716),"") | D32: =IFERROR(MEDIAN('SW Metrics'!$D$618:$D$716),"") | E32: =IFERROR(MEDIAN('SW Metrics'!$E$618:$E$716),"") | F32: =IFERROR(MEDIAN('SW Metrics'!$F$618:$F$716),"") | G32: =IFERROR(MEDIAN('SW Metrics'!$G$618:$G$716),"") | H32: =IFERROR(MEDIAN('SW Metrics'!$H$618:$H$716),"") | I32: =IFERROR(MEDIAN('SW Metrics'!$I$618:$I$716),"") | J32: =IFERROR(MEDIAN('SW Metrics'!$J$618:$J$716),"") | K32: =IFERROR(MEDIAN('SW Metrics'!$K$618:$K$716),"") | L32: =IFERROR(MEDIAN('SW Metrics'!$L$618:$L$716),"") | M32: =IFERROR(MEDIAN('SW Metrics'!$M$618:$M$716),"") | N32: =IFERROR(MEDIAN('SW Metrics'!$N$618:$N$716),"")
B33: vs median | C33: =IF(OR(C31="",C32=""),"",C31-C32) | D33: =IF(OR(D31="",D32=""),"",D31-D32) | E33: =IF(OR(E31="",E32=""),"",E31-E32) | F33: =IF(OR(F31="",F32=""),"",F31-F32) | G33: =IF(OR(G31="",G32=""),"",G31-G32) | H33: =IF(OR(H31="",H32=""),"",H31-H32) | I33: =IF(OR(I31="",I32=""),"",I31-I32) | J33: =IF(OR(J31="",J32=""),"",J31-J32) | ... N33: =IF(OR(N31="",N32=""),"",N31-N32)
A35: Op income YoY % | B35: Company | C35: =IFERROR(INDEX('SW Metrics'!$C$720:$C$818,MATCH($B$4,'SW Metrics'!$A$720:$A$818,0)),"") | D35: =IFERROR(INDEX('SW Metrics'!$D$720:$D$818,MATCH($B$4,'SW Metrics'!$A$720:$A$818,0)),"") | E35: =IFERROR(INDEX('SW Metrics'!$E$720:$E$818,MATCH($B$4,'SW Metrics'!$A$720:$A$818,0)),"") | F35: =IFERROR(INDEX('SW Metrics'!$F$720:$F$818,MATCH($B$4,'SW Metrics'!$A$720:$A$818,0)),"") | G35: =IFERROR(INDEX('SW Metrics'!$G$720:$G$818,MATCH($B$4,'SW Metrics'!$A$720:$A$818,0)),"") | H35: =IFERROR(INDEX('SW Metrics'!$H$720:$H$818,MATCH($B$4,'SW Metrics'!$A$720:$A$818,0)),"") | I35: =IFERROR(INDEX('SW Metrics'!$I$720:$I$818,MATCH($B$4,'SW Metrics'!$A$720:$A$818,0)),"") | J35: =IFERROR(INDEX('SW Metrics'!$J$720:$J$818,MATCH($B$4,'SW Metrics'!$A$720:$A$818,0)),"") | K35: =IFERROR(INDEX('SW Metrics'!$K$720:$K$818,MATCH($B$4,'SW Metrics'!$A$720:$A$818,0)),"") | L35: =IFERROR(INDEX('SW Metrics'!$L$720:$L$818,MATCH($B$4,'SW Metrics'!$A$720:$A$818,0)),"") | M35: =IFERROR(INDEX('SW Metrics'!$M$720:$M$818,MATCH($B$4,'SW Metrics'!$A$720:$A$818,0)),"") | N35: =IFERROR(INDEX('SW Metrics'!$N$720:$N$818,MATCH($B$4,'SW Metrics'!$A$720:$A$818,0)),"")
B36: Peer median | C36: =IFERROR(MEDIAN('SW Metrics'!$C$720:$C$818),"") | D36: =IFERROR(MEDIAN('SW Metrics'!$D$720:$D$818),"") | E36: =IFERROR(MEDIAN('SW Metrics'!$E$720:$E$818),"") | F36: =IFERROR(MEDIAN('SW Metrics'!$F$720:$F$818),"") | G36: =IFERROR(MEDIAN('SW Metrics'!$G$720:$G$818),"") | H36: =IFERROR(MEDIAN('SW Metrics'!$H$720:$H$818),"") | I36: =IFERROR(MEDIAN('SW Metrics'!$I$720:$I$818),"") | J36: =IFERROR(MEDIAN('SW Metrics'!$J$720:$J$818),"") | K36: =IFERROR(MEDIAN('SW Metrics'!$K$720:$K$818),"") | L36: =IFERROR(MEDIAN('SW Metrics'!$L$720:$L$818),"") | M36: =IFERROR(MEDIAN('SW Metrics'!$M$720:$M$818),"") | N36: =IFERROR(MEDIAN('SW Metrics'!$N$720:$N$818),"")
B37: vs median | C37: =IF(OR(C35="",C36=""),"",C35-C36) | D37: =IF(OR(D35="",D36=""),"",D35-D36) | E37: =IF(OR(E35="",E36=""),"",E35-E36) | F37: =IF(OR(F35="",F36=""),"",F35-F36) | G37: =IF(OR(G35="",G36=""),"",G35-G36) | H37: =IF(OR(H35="",H36=""),"",H35-H36) | I37: =IF(OR(I35="",I36=""),"",I35-I36) | J37: =IF(OR(J35="",J36=""),"",J35-J36) | ... N37: =IF(OR(N35="",N36=""),"",N35-N36)
A39: Incremental OpM % (leverage) | B39: Company | C39: =IFERROR(INDEX('SW Metrics'!$C$822:$C$920,MATCH($B$4,'SW Metrics'!$A$822:$A$920,0)),"") | D39: =IFERROR(INDEX('SW Metrics'!$D$822:$D$920,MATCH($B$4,'SW Metrics'!$A$822:$A$920,0)),"") | E39: =IFERROR(INDEX('SW Metrics'!$E$822:$E$920,MATCH($B$4,'SW Metrics'!$A$822:$A$920,0)),"") | F39: =IFERROR(INDEX('SW Metrics'!$F$822:$F$920,MATCH($B$4,'SW Metrics'!$A$822:$A$920,0)),"") | G39: =IFERROR(INDEX('SW Metrics'!$G$822:$G$920,MATCH($B$4,'SW Metrics'!$A$822:$A$920,0)),"") | H39: =IFERROR(INDEX('SW Metrics'!$H$822:$H$920,MATCH($B$4,'SW Metrics'!$A$822:$A$920,0)),"") | I39: =IFERROR(INDEX('SW Metrics'!$I$822:$I$920,MATCH($B$4,'SW Metrics'!$A$822:$A$920,0)),"") | J39: =IFERROR(INDEX('SW Metrics'!$J$822:$J$920,MATCH($B$4,'SW Metrics'!$A$822:$A$920,0)),"") | K39: =IFERROR(INDEX('SW Metrics'!$K$822:$K$920,MATCH($B$4,'SW Metrics'!$A$822:$A$920,0)),"") | L39: =IFERROR(INDEX('SW Metrics'!$L$822:$L$920,MATCH($B$4,'SW Metrics'!$A$822:$A$920,0)),"") | M39: =IFERROR(INDEX('SW Metrics'!$M$822:$M$920,MATCH($B$4,'SW Metrics'!$A$822:$A$920,0)),"") | N39: =IFERROR(INDEX('SW Metrics'!$N$822:$N$920,MATCH($B$4,'SW Metrics'!$A$822:$A$920,0)),"")
B40: Peer median | C40: =IFERROR(MEDIAN('SW Metrics'!$C$822:$C$920),"") | D40: =IFERROR(MEDIAN('SW Metrics'!$D$822:$D$920),"") | E40: =IFERROR(MEDIAN('SW Metrics'!$E$822:$E$920),"") | F40: =IFERROR(MEDIAN('SW Metrics'!$F$822:$F$920),"") | G40: =IFERROR(MEDIAN('SW Metrics'!$G$822:$G$920),"") | H40: =IFERROR(MEDIAN('SW Metrics'!$H$822:$H$920),"") | I40: =IFERROR(MEDIAN('SW Metrics'!$I$822:$I$920),"") | J40: =IFERROR(MEDIAN('SW Metrics'!$J$822:$J$920),"") | K40: =IFERROR(MEDIAN('SW Metrics'!$K$822:$K$920),"") | L40: =IFERROR(MEDIAN('SW Metrics'!$L$822:$L$920),"") | M40: =IFERROR(MEDIAN('SW Metrics'!$M$822:$M$920),"") | N40: =IFERROR(MEDIAN('SW Metrics'!$N$822:$N$920),"")
B41: vs median | C41: =IF(OR(C39="",C40=""),"",C39-C40) | D41: =IF(OR(D39="",D40=""),"",D39-D40) | E41: =IF(OR(E39="",E40=""),"",E39-E40) | F41: =IF(OR(F39="",F40=""),"",F39-F40) | G41: =IF(OR(G39="",G40=""),"",G39-G40) | H41: =IF(OR(H39="",H40=""),"",H39-H40) | I41: =IF(OR(I39="",I40=""),"",I39-I40) | J41: =IF(OR(J39="",J40=""),"",J39-J40) | ... N41: =IF(OR(N39="",N40=""),"",N39-N40)
A43: FCF margin LTM % | B43: Company | C43: =IFERROR(INDEX('SW Metrics'!$C$924:$C$1022,MATCH($B$4,'SW Metrics'!$A$924:$A$1022,0)),"") | D43: =IFERROR(INDEX('SW Metrics'!$D$924:$D$1022,MATCH($B$4,'SW Metrics'!$A$924:$A$1022,0)),"") | E43: =IFERROR(INDEX('SW Metrics'!$E$924:$E$1022,MATCH($B$4,'SW Metrics'!$A$924:$A$1022,0)),"") | F43: =IFERROR(INDEX('SW Metrics'!$F$924:$F$1022,MATCH($B$4,'SW Metrics'!$A$924:$A$1022,0)),"") | G43: =IFERROR(INDEX('SW Metrics'!$G$924:$G$1022,MATCH($B$4,'SW Metrics'!$A$924:$A$1022,0)),"") | H43: =IFERROR(INDEX('SW Metrics'!$H$924:$H$1022,MATCH($B$4,'SW Metrics'!$A$924:$A$1022,0)),"") | I43: =IFERROR(INDEX('SW Metrics'!$I$924:$I$1022,MATCH($B$4,'SW Metrics'!$A$924:$A$1022,0)),"") | J43: =IFERROR(INDEX('SW Metrics'!$J$924:$J$1022,MATCH($B$4,'SW Metrics'!$A$924:$A$1022,0)),"") | K43: =IFERROR(INDEX('SW Metrics'!$K$924:$K$1022,MATCH($B$4,'SW Metrics'!$A$924:$A$1022,0)),"") | L43: =IFERROR(INDEX('SW Metrics'!$L$924:$L$1022,MATCH($B$4,'SW Metrics'!$A$924:$A$1022,0)),"") | M43: =IFERROR(INDEX('SW Metrics'!$M$924:$M$1022,MATCH($B$4,'SW Metrics'!$A$924:$A$1022,0)),"") | N43: =IFERROR(INDEX('SW Metrics'!$N$924:$N$1022,MATCH($B$4,'SW Metrics'!$A$924:$A$1022,0)),"")
B44: Peer median | C44: =IFERROR(MEDIAN('SW Metrics'!$C$924:$C$1022),"") | D44: =IFERROR(MEDIAN('SW Metrics'!$D$924:$D$1022),"") | E44: =IFERROR(MEDIAN('SW Metrics'!$E$924:$E$1022),"") | F44: =IFERROR(MEDIAN('SW Metrics'!$F$924:$F$1022),"") | G44: =IFERROR(MEDIAN('SW Metrics'!$G$924:$G$1022),"") | H44: =IFERROR(MEDIAN('SW Metrics'!$H$924:$H$1022),"") | I44: =IFERROR(MEDIAN('SW Metrics'!$I$924:$I$1022),"") | J44: =IFERROR(MEDIAN('SW Metrics'!$J$924:$J$1022),"") | K44: =IFERROR(MEDIAN('SW Metrics'!$K$924:$K$1022),"") | L44: =IFERROR(MEDIAN('SW Metrics'!$L$924:$L$1022),"") | M44: =IFERROR(MEDIAN('SW Metrics'!$M$924:$M$1022),"") | N44: =IFERROR(MEDIAN('SW Metrics'!$N$924:$N$1022),"")
B45: vs median | C45: =IF(OR(C43="",C44=""),"",C43-C44) | D45: =IF(OR(D43="",D44=""),"",D43-D44) | E45: =IF(OR(E43="",E44=""),"",E43-E44) | F45: =IF(OR(F43="",F44=""),"",F43-F44) | G45: =IF(OR(G43="",G44=""),"",G43-G44) | H45: =IF(OR(H43="",H44=""),"",H43-H44) | I45: =IF(OR(I43="",I44=""),"",I43-I44) | J45: =IF(OR(J43="",J44=""),"",J43-J44) | ... N45: =IF(OR(N43="",N44=""),"",N43-N44)
A47: FCF margin Δ YoY (bps) | B47: Company | C47: =IFERROR(INDEX('SW Metrics'!$C$1026:$C$1124,MATCH($B$4,'SW Metrics'!$A$1026:$A$1124,0)),"") | D47: =IFERROR(INDEX('SW Metrics'!$D$1026:$D$1124,MATCH($B$4,'SW Metrics'!$A$1026:$A$1124,0)),"") | E47: =IFERROR(INDEX('SW Metrics'!$E$1026:$E$1124,MATCH($B$4,'SW Metrics'!$A$1026:$A$1124,0)),"") | F47: =IFERROR(INDEX('SW Metrics'!$F$1026:$F$1124,MATCH($B$4,'SW Metrics'!$A$1026:$A$1124,0)),"") | G47: =IFERROR(INDEX('SW Metrics'!$G$1026:$G$1124,MATCH($B$4,'SW Metrics'!$A$1026:$A$1124,0)),"") | H47: =IFERROR(INDEX('SW Metrics'!$H$1026:$H$1124,MATCH($B$4,'SW Metrics'!$A$1026:$A$1124,0)),"") | I47: =IFERROR(INDEX('SW Metrics'!$I$1026:$I$1124,MATCH($B$4,'SW Metrics'!$A$1026:$A$1124,0)),"") | J47: =IFERROR(INDEX('SW Metrics'!$J$1026:$J$1124,MATCH($B$4,'SW Metrics'!$A$1026:$A$1124,0)),"") | K47: =IFERROR(INDEX('SW Metrics'!$K$1026:$K$1124,MATCH($B$4,'SW Metrics'!$A$1026:$A$1124,0)),"") | L47: =IFERROR(INDEX('SW Metrics'!$L$1026:$L$1124,MATCH($B$4,'SW Metrics'!$A$1026:$A$1124,0)),"") | M47: =IFERROR(INDEX('SW Metrics'!$M$1026:$M$1124,MATCH($B$4,'SW Metrics'!$A$1026:$A$1124,0)),"") | N47: =IFERROR(INDEX('SW Metrics'!$N$1026:$N$1124,MATCH($B$4,'SW Metrics'!$A$1026:$A$1124,0)),"")
B48: Peer median | C48: =IFERROR(MEDIAN('SW Metrics'!$C$1026:$C$1124),"") | D48: =IFERROR(MEDIAN('SW Metrics'!$D$1026:$D$1124),"") | E48: =IFERROR(MEDIAN('SW Metrics'!$E$1026:$E$1124),"") | F48: =IFERROR(MEDIAN('SW Metrics'!$F$1026:$F$1124),"") | G48: =IFERROR(MEDIAN('SW Metrics'!$G$1026:$G$1124),"") | H48: =IFERROR(MEDIAN('SW Metrics'!$H$1026:$H$1124),"") | I48: =IFERROR(MEDIAN('SW Metrics'!$I$1026:$I$1124),"") | J48: =IFERROR(MEDIAN('SW Metrics'!$J$1026:$J$1124),"") | K48: =IFERROR(MEDIAN('SW Metrics'!$K$1026:$K$1124),"") | L48: =IFERROR(MEDIAN('SW Metrics'!$L$1026:$L$1124),"") | M48: =IFERROR(MEDIAN('SW Metrics'!$M$1026:$M$1124),"") | N48: =IFERROR(MEDIAN('SW Metrics'!$N$1026:$N$1124),"")
B49: vs median | C49: =IF(OR(C47="",C48=""),"",C47-C48) | D49: =IF(OR(D47="",D48=""),"",D47-D48) | E49: =IF(OR(E47="",E48=""),"",E47-E48) | F49: =IF(OR(F47="",F48=""),"",F47-F48) | G49: =IF(OR(G47="",G48=""),"",G47-G48) | H49: =IF(OR(H47="",H48=""),"",H47-H48) | I49: =IF(OR(I47="",I48=""),"",I47-I48) | J49: =IF(OR(J47="",J48=""),"",J47-J48) | ... N49: =IF(OR(N47="",N48=""),"",N47-N48)
A51: NTM estimate revisions
A52: Metric | B52: Series | C52: Δ1M % | D52: Δ3M % | E52: Δ6M %
A53: NTM Revenue revision | B53: Company | C53: =IFERROR(INDEX('SW Revisions'!$G$6:$G$104,MATCH($B$4,'SW Revisions'!$A$6:$A$104,0)),"") | D53: =IFERROR(INDEX('SW Revisions'!$H$6:$H$104,MATCH($B$4,'SW Revisions'!$A$6:$A$104,0)),"") | E53: =IFERROR(INDEX('SW Revisions'!$I$6:$I$104,MATCH($B$4,'SW Revisions'!$A$6:$A$104,0)),"")
...

Sheet SW Metrics
A1: Software — Metric Grids (by fiscal period offset) | H1: ⚠ Cells blank? This is a LIVE Bloomberg workbook — it has no saved data until its first refresh. Open it in desktop Excel on your Bloomberg terminal PC (add-in logged in), then Bloomberg ribbon ▸ Refresh All (or Ctrl+Alt+F9), wait a few minutes, and save. See README.
A2: All inputs from the BQL data sheets. FPO 0 = latest reported quarter per company; +1/+2 = consensus estimates (shaded). Blank cells = insufficient history / no estimate. Hover column headers and block titles for definitions.
A4: Revenue (USD mm)
A5: Ticker | B5: Latest Rpt Qtr | C5: FPO -9 | D5: FPO -8 | E5: FPO -7 | F5: FPO -6 | G5: FPO -5 | H5: FPO -4 | I5: FPO -3 | J5: FPO -2 | K5: FPO -1 | L5: FPO 0 (latest rpt) | M5: FPO +1E | N5: FPO +2E
A6: ='SW Rev'!$A5 | B6: ='SW Rev'!$B5 | C6: =IFERROR(IF(ISNUMBER('SW Rev'!G5),'SW Rev'!G5,""),"") | D6: =IFERROR(IF(ISNUMBER('SW Rev'!H5),'SW Rev'!H5,""),"") | E6: =IFERROR(IF(ISNUMBER('SW Rev'!I5),'SW Rev'!I5,""),"") | F6: =IFERROR(IF(ISNUMBER('SW Rev'!J5),'SW Rev'!J5,""),"") | G6: =IFERROR(IF(ISNUMBER('SW Rev'!K5),'SW Rev'!K5,""),"") | H6: =IFERROR(IF(ISNUMBER('SW Rev'!L5),'SW Rev'!L5,""),"") | I6: =IFERROR(IF(ISNUMBER('SW Rev'!M5),'SW Rev'!M5,""),"") | J6: =IFERROR(IF(ISNUMBER('SW Rev'!N5),'SW Rev'!N5,""),"") | ... N6: =IFERROR(IF(ISNUMBER('SW Rev'!R5),'SW Rev'!R5,""),"")
A7: ='SW Rev'!$A6 | B7: ='SW Rev'!$B6 | C7: =IFERROR(IF(ISNUMBER('SW Rev'!G6),'SW Rev'!G6,""),"") | D7: =IFERROR(IF(ISNUMBER('SW Rev'!H6),'SW Rev'!H6,""),"") | E7: =IFERROR(IF(ISNUMBER('SW Rev'!I6),'SW Rev'!I6,""),"") | F7: =IFERROR(IF(ISNUMBER('SW Rev'!J6),'SW Rev'!J6,""),"") | G7: =IFERROR(IF(ISNUMBER('SW Rev'!K6),'SW Rev'!K6,""),"") | H7: =IFERROR(IF(ISNUMBER('SW Rev'!L6),'SW Rev'!L6,""),"") | I7: =IFERROR(IF(ISNUMBER('SW Rev'!M6),'SW Rev'!M6,""),"") | J7: =IFERROR(IF(ISNUMBER('SW Rev'!N6),'SW Rev'!N6,""),"") | ... N7: =IFERROR(IF(ISNUMBER('SW Rev'!R6),'SW Rev'!R6,""),"")
A8: ='SW Rev'!$A7 | B8: ='SW Rev'!$B7 | C8: =IFERROR(IF(ISNUMBER('SW Rev'!G7),'SW Rev'!G7,""),"") | D8: =IFERROR(IF(ISNUMBER('SW Rev'!H7),'SW Rev'!H7,""),"") | E8: =IFERROR(IF(ISNUMBER('SW Rev'!I7),'SW Rev'!I7,""),"") | F8: =IFERROR(IF(ISNUMBER('SW Rev'!J7),'SW Rev'!J7,""),"") | G8: =IFERROR(IF(ISNUMBER('SW Rev'!K7),'SW Rev'!K7,""),"") | H8: =IFERROR(IF(ISNUMBER('SW Rev'!L7),'SW Rev'!L7,""),"") | I8: =IFERROR(IF(ISNUMBER('SW Rev'!M7),'SW Rev'!M7,""),"") | J8: =IFERROR(IF(ISNUMBER('SW Rev'!N7),'SW Rev'!N7,""),"") | ... N8: =IFERROR(IF(ISNUMBER('SW Rev'!R7),'SW Rev'!R7,""),"")
A9: ='SW Rev'!$A8 | B9: ='SW Rev'!$B8 | C9: =IFERROR(IF(ISNUMBER('SW Rev'!G8),'SW Rev'!G8,""),"") | D9: =IFERROR(IF(ISNUMBER('SW Rev'!H8),'SW Rev'!H8,""),"") | E9: =IFERROR(IF(ISNUMBER('SW Rev'!I8),'SW Rev'!I8,""),"") | F9: =IFERROR(IF(ISNUMBER('SW Rev'!J8),'SW Rev'!J8,""),"") | G9: =IFERROR(IF(ISNUMBER('SW Rev'!K8),'SW Rev'!K8,""),"") | H9: =IFERROR(IF(ISNUMBER('SW Rev'!L8),'SW Rev'!L8,""),"") | I9: =IFERROR(IF(ISNUMBER('SW Rev'!M8),'SW Rev'!M8,""),"") | J9: =IFERROR(IF(ISNUMBER('SW Rev'!N8),'SW Rev'!N8,""),"") | ... N9: =IFERROR(IF(ISNUMBER('SW Rev'!R8),'SW Rev'!R8,""),"")
A10: ='SW Rev'!$A9 | B10: ='SW Rev'!$B9 | C10: =IFERROR(IF(ISNUMBER('SW Rev'!G9),'SW Rev'!G9,""),"") | D10: =IFERROR(IF(ISNUMBER('SW Rev'!H9),'SW Rev'!H9,""),"") | E10: =IFERROR(IF(ISNUMBER('SW Rev'!I9),'SW Rev'!I9,""),"") | F10: =IFERROR(IF(ISNUMBER('SW Rev'!J9),'SW Rev'!J9,""),"") | G10: =IFERROR(IF(ISNUMBER('SW Rev'!K9),'SW Rev'!K9,""),"") | H10: =IFERROR(IF(ISNUMBER('SW Rev'!L9),'SW Rev'!L9,""),"") | I10: =IFERROR(IF(ISNUMBER('SW Rev'!M9),'SW Rev'!M9,""),"") | J10: =IFERROR(IF(ISNUMBER('SW Rev'!N9),'SW Rev'!N9,""),"") | ... N10: =IFERROR(IF(ISNUMBER('SW Rev'!R9),'SW Rev'!R9,""),"")
A11: ='SW Rev'!$A10 | B11: ='SW Rev'!$B10 | C11: =IFERROR(IF(ISNUMBER('SW Rev'!G10),'SW Rev'!G10,""),"") | D11: =IFERROR(IF(ISNUMBER('SW Rev'!H10),'SW Rev'!H10,""),"") | E11: =IFERROR(IF(ISNUMBER('SW Rev'!I10),'SW Rev'!I10,""),"") | F11: =IFERROR(IF(ISNUMBER('SW Rev'!J10),'SW Rev'!J10,""),"") | G11: =IFERROR(IF(ISNUMBER('SW Rev'!K10),'SW Rev'!K10,""),"") | H11: =IFERROR(IF(ISNUMBER('SW Rev'!L10),'SW Rev'!L10,""),"") | I11: =IFERROR(IF(ISNUMBER('SW Rev'!M10),'SW Rev'!M10,""),"") | J11: =IFERROR(IF(ISNUMBER('SW Rev'!N10),'SW Rev'!N10,""),"") | ... N11: =IFERROR(IF(ISNUMBER('SW Rev'!R10),'SW Rev'!R10,""),"")
A12: ='SW Rev'!$A11 | B12: ='SW Rev'!$B11 | C12: =IFERROR(IF(ISNUMBER('SW Rev'!G11),'SW Rev'!G11,""),"") | D12: =IFERROR(IF(ISNUMBER('SW Rev'!H11),'SW Rev'!H11,""),"") | E12: =IFERROR(IF(ISNUMBER('SW Rev'!I11),'SW Rev'!I11,""),"") | F12: =IFERROR(IF(ISNUMBER('SW Rev'!J11),'SW Rev'!J11,""),"") | G12: =IFERROR(IF(ISNUMBER('SW Rev'!K11),'SW Rev'!K11,""),"") | H12: =IFERROR(IF(ISNUMBER('SW Rev'!L11),'SW Rev'!L11,""),"") | I12: =IFERROR(IF(ISNUMBER('SW Rev'!M11),'SW Rev'!M11,""),"") | J12: =IFERROR(IF(ISNUMBER('SW Rev'!N11),'SW Rev'!N11,""),"") | ... N12: =IFERROR(IF(ISNUMBER('SW Rev'!R11),'SW Rev'!R11,""),"")
A13: ='SW Rev'!$A12 | B13: ='SW Rev'!$B12 | C13: =IFERROR(IF(ISNUMBER('SW Rev'!G12),'SW Rev'!G12,""),"") | D13: =IFERROR(IF(ISNUMBER('SW Rev'!H12),'SW Rev'!H12,""),"") | E13: =IFERROR(IF(ISNUMBER('SW Rev'!I12),'SW Rev'!I12,""),"") | F13: =IFERROR(IF(ISNUMBER('SW Rev'!J12),'SW Rev'!J12,""),"") | G13: =IFERROR(IF(ISNUMBER('SW Rev'!K12),'SW Rev'!K12,""),"") | H13: =IFERROR(IF(ISNUMBER('SW Rev'!L12),'SW Rev'!L12,""),"") | I13: =IFERROR(IF(ISNUMBER('SW Rev'!M12),'SW Rev'!M12,""),"") | J13: =IFERROR(IF(ISNUMBER('SW Rev'!N12),'SW Rev'!N12,""),"") | ... N13: =IFERROR(IF(ISNUMBER('SW Rev'!R12),'SW Rev'!R12,""),"")
A14: ='SW Rev'!$A13 | B14: ='SW Rev'!$B13 | C14: =IFERROR(IF(ISNUMBER('SW Rev'!G13),'SW Rev'!G13,""),"") | D14: =IFERROR(IF(ISNUMBER('SW Rev'!H13),'SW Rev'!H13,""),"") | E14: =IFERROR(IF(ISNUMBER('SW Rev'!I13),'SW Rev'!I13,""),"") | F14: =IFERROR(IF(ISNUMBER('SW Rev'!J13),'SW Rev'!J13,""),"") | G14: =IFERROR(IF(ISNUMBER('SW Rev'!K13),'SW Rev'!K13,""),"") | H14: =IFERROR(IF(ISNUMBER('SW Rev'!L13),'SW Rev'!L13,""),"") | I14: =IFERROR(IF(ISNUMBER('SW Rev'!M13),'SW Rev'!M13,""),"") | J14: =IFERROR(IF(ISNUMBER('SW Rev'!N13),'SW Rev'!N13,""),"") | ... N14: =IFERROR(IF(ISNUMBER('SW Rev'!R13),'SW Rev'!R13,""),"")
A15: ='SW Rev'!$A14 | B15: ='SW Rev'!$B14 | C15: =IFERROR(IF(ISNUMBER('SW Rev'!G14),'SW Rev'!G14,""),"") | D15: =IFERROR(IF(ISNUMBER('SW Rev'!H14),'SW Rev'!H14,""),"") | E15: =IFERROR(IF(ISNUMBER('SW Rev'!I14),'SW Rev'!I14,""),"") | F15: =IFERROR(IF(ISNUMBER('SW Rev'!J14),'SW Rev'!J14,""),"") | G15: =IFERROR(IF(ISNUMBER('SW Rev'!K14),'SW Rev'!K14,""),"") | H15: =IFERROR(IF(ISNUMBER('SW Rev'!L14),'SW Rev'!L14,""),"") | I15: =IFERROR(IF(ISNUMBER('SW Rev'!M14),'SW Rev'!M14,""),"") | J15: =IFERROR(IF(ISNUMBER('SW Rev'!N14),'SW Rev'!N14,""),"") | ... N15: =IFERROR(IF(ISNUMBER('SW Rev'!R14),'SW Rev'!R14,""),"")
A16: ='SW Rev'!$A15 | B16: ='SW Rev'!$B15 | C16: =IFERROR(IF(ISNUMBER('SW Rev'!G15),'SW Rev'!G15,""),"") | D16: =IFERROR(IF(ISNUMBER('SW Rev'!H15),'SW Rev'!H15,""),"") | E16: =IFERROR(IF(ISNUMBER('SW Rev'!I15),'SW Rev'!I15,""),"") | F16: =IFERROR(IF(ISNUMBER('SW Rev'!J15),'SW Rev'!J15,""),"") | G16: =IFERROR(IF(ISNUMBER('SW Rev'!K15),'SW Rev'!K15,""),"") | H16: =IFERROR(IF(ISNUMBER('SW Rev'!L15),'SW Rev'!L15,""),"") | I16: =IFERROR(IF(ISNUMBER('SW Rev'!M15),'SW Rev'!M15,""),"") | J16: =IFERROR(IF(ISNUMBER('SW Rev'!N15),'SW Rev'!N15,""),"") | ... N16: =IFERROR(IF(ISNUMBER('SW Rev'!R15),'SW Rev'!R15,""),"")
A17: ='SW Rev'!$A16 | B17: ='SW Rev'!$B16 | C17: =IFERROR(IF(ISNUMBER('SW Rev'!G16),'SW Rev'!G16,""),"") | D17: =IFERROR(IF(ISNUMBER('SW Rev'!H16),'SW Rev'!H16,""),"") | E17: =IFERROR(IF(ISNUMBER('SW Rev'!I16),'SW Rev'!I16,""),"") | F17: =IFERROR(IF(ISNUMBER('SW Rev'!J16),'SW Rev'!J16,""),"") | G17: =IFERROR(IF(ISNUMBER('SW Rev'!K16),'SW Rev'!K16,""),"") | H17: =IFERROR(IF(ISNUMBER('SW Rev'!L16),'SW Rev'!L16,""),"") | I17: =IFERROR(IF(ISNUMBER('SW Rev'!M16),'SW Rev'!M16,""),"") | J17: =IFERROR(IF(ISNUMBER('SW Rev'!N16),'SW Rev'!N16,""),"") | ... N17: =IFERROR(IF(ISNUMBER('SW Rev'!R16),'SW Rev'!R16,""),"")
... A104: ='SW Rev'!$A103 | B104: ='SW Rev'!$B103 | C104: =IFERROR(IF(ISNUMBER('SW Rev'!G103),'SW Rev'!G103,""),"") | D104: =IFERROR(IF(ISNUMBER('SW Rev'!H103),'SW Rev'!H103,""),"") | E104: =IFERROR(IF(ISNUMBER('SW Rev'!I103),'SW Rev'!I103,""),"") | F104: =IFERROR(IF(ISNUMBER('SW Rev'!J103),'SW Rev'!J103,""),"") | G104: =IFERROR(IF(ISNUMBER('SW Rev'!K103),'SW Rev'!K103,""),"") | H104: =IFERROR(IF(ISNUMBER('SW Rev'!L103),'SW Rev'!L103,""),"") | I104: =IFERROR(IF(ISNUMBER('SW Rev'!M103),'SW Rev'!M103,""),"") | J104: =IFERROR(IF(ISNUMBER('SW Rev'!N103),'SW Rev'!N103,""),"") | ... N104: =IFERROR(IF(ISNUMBER('SW Rev'!R103),'SW Rev'!R103,""),"")
A106: Revenue growth YoY %
A107: Ticker | B107: Latest Rpt Qtr | C107: FPO -9 | D107: FPO -8 | E107: FPO -7 | F107: FPO -6 | G107: FPO -5 | H107: FPO -4 | I107: FPO -3 | J107: FPO -2 | K107: FPO -1 | L107: FPO 0 (latest rpt) | M107: FPO +1E | N107: FPO +2E
A108: ='SW Rev'!$A5 | B108: ='SW Rev'!$B5 | C108: =IFERROR(IF(AND(ISNUMBER('SW Rev'!G5),ISNUMBER('SW Rev'!C5),'SW Rev'!C5>0),'SW Rev'!G5/'SW Rev'!C5-1,""),"") | D108: =IFERROR(IF(AND(ISNUMBER('SW Rev'!H5),ISNUMBER('SW Rev'!D5),'SW Rev'!D5>0),'SW Rev'!H5/'SW Rev'!D5-1,""),"") | E108: =IFERROR(IF(AND(ISNUMBER('SW Rev'!I5),ISNUMBER('SW Rev'!E5),'SW Rev'!E5>0),'SW Rev'!I5/'SW Rev'!E5-1,""),"") | F108: =IFERROR(IF(AND(ISNUMBER('SW Rev'!J5),ISNUMBER('SW Rev'!F5),'SW Rev'!F5>0),'SW Rev'!J5/'SW Rev'!F5-1,""),"") | G108: =IFERROR(IF(AND(ISNUMBER('SW Rev'!K5),ISNUMBER('SW Rev'!G5),'SW Rev'!G5>0),'SW Rev'!K5/'SW Rev'!G5-1,""),"") | H108: =IFERROR(IF(AND(ISNUMBER('SW Rev'!L5),ISNUMBER('SW Rev'!H5),'SW Rev'!H5>0),'SW Rev'!L5/'SW Rev'!H5-1,""),"") | I108: =IFERROR(IF(AND(ISNUMBER('SW Rev'!M5),ISNUMBER('SW Rev'!I5),'SW Rev'!I5>0),'SW Rev'!M5/'SW Rev'!I5-1,""),"") | J108: =IFERROR(IF(AND(ISNUMBER('SW Rev'!N5),ISNUMBER('SW Rev'!J5),'SW Rev'!J5>0),'SW Rev'!N5/'SW Rev'!J5-1,""),"") | ... N108: =IFERROR(IF(AND(ISNUMBER('SW Rev'!R5),ISNUMBER('SW Rev'!N5),'SW Rev'!N5>0),'SW Rev'!R5/'SW Rev'!N5-1,""),"")
A109: ='SW Rev'!$A6 | B109: ='SW Rev'!$B6 | C109: =IFERROR(IF(AND(ISNUMBER('SW Rev'!G6),ISNUMBER('SW Rev'!C6),'SW Rev'!C6>0),'SW Rev'!G6/'SW Rev'!C6-1,""),"") | D109: =IFERROR(IF(AND(ISNUMBER('SW Rev'!H6),ISNUMBER('SW Rev'!D6),'SW Rev'!D6>0),'SW Rev'!H6/'SW Rev'!D6-1,""),"") | E109: =IFERROR(IF(AND(ISNUMBER('SW Rev'!I6),ISNUMBER('SW Rev'!E6),'SW Rev'!E6>0),'SW Rev'!I6/'SW Rev'!E6-1,""),"") | F109: =IFERROR(IF(AND(ISNUMBER('SW Rev'!J6),ISNUMBER('SW Rev'!F6),'SW Rev'!F6>0),'SW Rev'!J6/'SW Rev'!F6-1,""),"") | G109: =IFERROR(IF(AND(ISNUMBER('SW Rev'!K6),ISNUMBER('SW Rev'!G6),'SW Rev'!G6>0),'SW Rev'!K6/'SW Rev'!G6-1,""),"") | H109: =IFERROR(IF(AND(ISNUMBER('SW Rev'!L6),ISNUMBER('SW Rev'!H6),'SW Rev'!H6>0),'SW Rev'!L6/'SW Rev'!H6-1,""),"") | I109: =IFERROR(IF(AND(ISNUMBER('SW Rev'!M6),ISNUMBER('SW Rev'!I6),'SW Rev'!I6>0),'SW Rev'!M6/'SW Rev'!I6-1,""),"") | J109: =IFERROR(IF(AND(ISNUMBER('SW Rev'!N6),ISNUMBER('SW Rev'!J6),'SW Rev'!J6>0),'SW Rev'!N6/'SW Rev'!J6-1,""),"") | ... N109: =IFERROR(IF(AND(ISNUMBER('SW Rev'!R6),ISNUMBER('SW Rev'!N6),'SW Rev'!N6>0),'SW Rev'!R6/'SW Rev'!N6-1,""),"")
A110: ='SW Rev'!$A7 | B110: ='SW Rev'!$B7 | C110: =IFERROR(IF(AND(ISNUMBER('SW Rev'!G7),ISNUMBER('SW Rev'!C7),'SW Rev'!C7>0),'SW Rev'!G7/'SW Rev'!C7-1,""),"") | D110: =IFERROR(IF(AND(ISNUMBER('SW Rev'!H7),ISNUMBER('SW Rev'!D7),'SW Rev'!D7>0),'SW Rev'!H7/'SW Rev'!D7-1,""),"") | E110: =IFERROR(IF(AND(ISNUMBER('SW Rev'!I7),ISNUMBER('SW Rev'!E7),'SW Rev'!E7>0),'SW Rev'!I7/'SW Rev'!E7-1,""),"") | F110: =IFERROR(IF(AND(ISNUMBER('SW Rev'!J7),ISNUMBER('SW Rev'!F7),'SW Rev'!F7>0),'SW Rev'!J7/'SW Rev'!F7-1,""),"") | G110: =IFERROR(IF(AND(ISNUMBER('SW Rev'!K7),ISNUMBER('SW Rev'!G7),'SW Rev'!G7>0),'SW Rev'!K7/'SW Rev'!G7-1,""),"") | H110: =IFERROR(IF(AND(ISNUMBER('SW Rev'!L7),ISNUMBER('SW Rev'!H7),'SW Rev'!H7>0),'SW Rev'!L7/'SW Rev'!H7-1,""),"") | I110: =IFERROR(IF(AND(ISNUMBER('SW Rev'!M7),ISNUMBER('SW Rev'!I7),'SW Rev'!I7>0),'SW Rev'!M7/'SW Rev'!I7-1,""),"") | J110: =IFERROR(IF(AND(ISNUMBER('SW Rev'!N7),ISNUMBER('SW Rev'!J7),'SW Rev'!J7>0),'SW Rev'!N7/'SW Rev'!J7-1,""),"") | ... N110: =IFERROR(IF(AND(ISNUMBER('SW Rev'!R7),ISNUMBER('SW Rev'!N7),'SW Rev'!N7>0),'SW Rev'!R7/'SW Rev'!N7-1,""),"")
A111: ='SW Rev'!$A8 | B111: ='SW Rev'!$B8 | C111: =IFERROR(IF(AND(ISNUMBER('SW Rev'!G8),ISNUMBER('SW Rev'!C8),'SW Rev'!C8>0),'SW Rev'!G8/'SW Rev'!C8-1,""),"") | D111: =IFERROR(IF(AND(ISNUMBER('SW Rev'!H8),ISNUMBER('SW Rev'!D8),'SW Rev'!D8>0),'SW Rev'!H8/'SW Rev'!D8-1,""),"") | E111: =IFERROR(IF(AND(ISNUMBER('SW Rev'!I8),ISNUMBER('SW Rev'!E8),'SW Rev'!E8>0),'SW Rev'!I8/'SW Rev'!E8-1,""),"") | F111: =IFERROR(IF(AND(ISNUMBER('SW Rev'!J8),ISNUMBER('SW Rev'!F8),'SW Rev'!F8>0),'SW Rev'!J8/'SW Rev'!F8-1,""),"") | G111: =IFERROR(IF(AND(ISNUMBER('SW Rev'!K8),ISNUMBER('SW Rev'!G8),'SW Rev'!G8>0),'SW Rev'!K8/'SW Rev'!G8-1,""),"") | H111: =IFERROR(IF(AND(ISNUMBER('SW Rev'!L8),ISNUMBER('SW Rev'!H8),'SW Rev'!H8>0),'SW Rev'!L8/'SW Rev'!H8-1,""),"") | I111: =IFERROR(IF(AND(ISNUMBER('SW Rev'!M8),ISNUMBER('SW Rev'!I8),'SW Rev'!I8>0),'SW Rev'!M8/'SW Rev'!I8-1,""),"") | J111: =IFERROR(IF(AND(ISNUMBER('SW Rev'!N8),ISNUMBER('SW Rev'!J8),'SW Rev'!J8>0),'SW Rev'!N8/'SW Rev'!J8-1,""),"") | ... N111: =IFERROR(IF(AND(ISNUMBER('SW Rev'!R8),ISNUMBER('SW Rev'!N8),'SW Rev'!N8>0),'SW Rev'!R8/'SW Rev'!N8-1,""),"")
A112: ='SW Rev'!$A9 | B112: ='SW Rev'!$B9 | C112: =IFERROR(IF(AND(ISNUMBER('SW Rev'!G9),ISNUMBER('SW Rev'!C9),'SW Rev'!C9>0),'SW Rev'!G9/'SW Rev'!C9-1,""),"") | D112: =IFERROR(IF(AND(ISNUMBER('SW Rev'!H9),ISNUMBER('SW Rev'!D9),'SW Rev'!D9>0),'SW Rev'!H9/'SW Rev'!D9-1,""),"") | E112: =IFERROR(IF(AND(ISNUMBER('SW Rev'!I9),ISNUMBER('SW Rev'!E9),'SW Rev'!E9>0),'SW Rev'!I9/'SW Rev'!E9-1,""),"") | F112: =IFERROR(IF(AND(ISNUMBER('SW Rev'!J9),ISNUMBER('SW Rev'!F9),'SW Rev'!F9>0),'SW Rev'!J9/'SW Rev'!F9-1,""),"") | G112: =IFERROR(IF(AND(ISNUMBER('SW Rev'!K9),ISNUMBER('SW Rev'!G9),'SW Rev'!G9>0),'SW Rev'!K9/'SW Rev'!G9-1,""),"") | H112: =IFERROR(IF(AND(ISNUMBER('SW Rev'!L9),ISNUMBER('SW Rev'!H9),'SW Rev'!H9>0),'SW Rev'!L9/'SW Rev'!H9-1,""),"") | I112: =IFERROR(IF(AND(ISNUMBER('SW Rev'!M9),ISNUMBER('SW Rev'!I9),'SW Rev'!I9>0),'SW Rev'!M9/'SW Rev'!I9-1,""),"") | J112: =IFERROR(IF(AND(ISNUMBER('SW Rev'!N9),ISNUMBER('SW Rev'!J9),'SW Rev'!J9>0),'SW Rev'!N9/'SW Rev'!J9-1,""),"") | ... N112: =IFERROR(IF(AND(ISNUMBER('SW Rev'!R9),ISNUMBER('SW Rev'!N9),'SW Rev'!N9>0),'SW Rev'!R9/'SW Rev'!N9-1,""),"")
A113: ='SW Rev'!$A10 | B113: ='SW Rev'!$B10 | C113: =IFERROR(IF(AND(ISNUMBER('SW Rev'!G10),ISNUMBER('SW Rev'!C10),'SW Rev'!C10>0),'SW Rev'!G10/'SW Rev'!C10-1,""),"") | D113: =IFERROR(IF(AND(ISNUMBER('SW Rev'!H10),ISNUMBER('SW Rev'!D10),'SW Rev'!D10>0),'SW Rev'!H10/'SW Rev'!D10-1,""),"") | E113: =IFERROR(IF(AND(ISNUMBER('SW Rev'!I10),ISNUMBER('SW Rev'!E10),'SW Rev'!E10>0),'SW Rev'!I10/'SW Rev'!E10-1,""),"") | F113: =IFERROR(IF(AND(ISNUMBER('SW Rev'!J10),ISNUMBER('SW Rev'!F10),'SW Rev'!F10>0),'SW Rev'!J10/'SW Rev'!F10-1,""),"") | G113: =IFERROR(IF(AND(ISNUMBER('SW Rev'!K10),ISNUMBER('SW Rev'!G10),'SW Rev'!G10>0),'SW Rev'!K10/'SW Rev'!G10-1,""),"") | H113: =IFERROR(IF(AND(ISNUMBER('SW Rev'!L10),ISNUMBER('SW Rev'!H10),'SW Rev'!H10>0),'SW Rev'!L10/'SW Rev'!H10-1,""),"") | I113: =IFERROR(IF(AND(ISNUMBER('SW Rev'!M10),ISNUMBER('SW Rev'!I10),'SW Rev'!I10>0),'SW Rev'!M10/'SW Rev'!I10-1,""),"") | J113: =IFERROR(IF(AND(ISNUMBER('SW Rev'!N10),ISNUMBER('SW Rev'!J10),'SW Rev'!J10>0),'SW Rev'!N10/'SW Rev'!J10-1,""),"") | ... N113: =IFERROR(IF(AND(ISNUMBER('SW Rev'!R10),ISNUMBER('SW Rev'!N10),'SW Rev'!N10>0),'SW Rev'!R10/'SW Rev'!N10-1,""),"")
A114: ='SW Rev'!$A11 | B114: ='SW Rev'!$B11 | C114: =IFERROR(IF(AND(ISNUMBER('SW Rev'!G11),ISNUMBER('SW Rev'!C11),'SW Rev'!C11>0),'SW Rev'!G11/'SW Rev'!C11-1,""),"") | D114: =IFERROR(IF(AND(ISNUMBER('SW Rev'!H11),ISNUMBER('SW Rev'!D11),'SW Rev'!D11>0),'SW Rev'!H11/'SW Rev'!D11-1,""),"") | E114: =IFERROR(IF(AND(ISNUMBER('SW Rev'!I11),ISNUMBER('SW Rev'!E11),'SW Rev'!E11>0),'SW Rev'!I11/'SW Rev'!E11-1,""),"") | F114: =IFERROR(IF(AND(ISNUMBER('SW Rev'!J11),ISNUMBER('SW Rev'!F11),'SW Rev'!F11>0),'SW Rev'!J11/'SW Rev'!F11-1,""),"") | G114: =IFERROR(IF(AND(ISNUMBER('SW Rev'!K11),ISNUMBER('SW Rev'!G11),'SW Rev'!G11>0),'SW Rev'!K11/'SW Rev'!G11-1,""),"") | H114: =IFERROR(IF(AND(ISNUMBER('SW Rev'!L11),ISNUMBER('SW Rev'!H11),'SW Rev'!H11>0),'SW Rev'!L11/'SW Rev'!H11-1,""),"") | I114: =IFERROR(IF(AND(ISNUMBER('SW Rev'!M11),ISNUMBER('SW Rev'!I11),'SW Rev'!I11>0),'SW Rev'!M11/'SW Rev'!I11-1,""),"") | J114: =IFERROR(IF(AND(ISNUMBER('SW Rev'!N11),ISNUMBER('SW Rev'!J11),'SW Rev'!J11>0),'SW Rev'!N11/'SW Rev'!J11-1,""),"") | ... N114: =IFERROR(IF(AND(ISNUMBER('SW Rev'!R11),ISNUMBER('SW Rev'!N11),'SW Rev'!N11>0),'SW Rev'!R11/'SW Rev'!N11-1,""),"")
A115: ='SW Rev'!$A12 | B115: ='SW Rev'!$B12 | C115: =IFERROR(IF(AND(ISNUMBER('SW Rev'!G12),ISNUMBER('SW Rev'!C12),'SW Rev'!C12>0),'SW Rev'!G12/'SW Rev'!C12-1,""),"") | D115: =IFERROR(IF(AND(ISNUMBER('SW Rev'!H12),ISNUMBER('SW Rev'!D12),'SW Rev'!D12>0),'SW Rev'!H12/'SW Rev'!D12-1,""),"") | E115: =IFERROR(IF(AND(ISNUMBER('SW Rev'!I12),ISNUMBER('SW Rev'!E12),'SW Rev'!E12>0),'SW Rev'!I12/'SW Rev'!E12-1,""),"") | F115: =IFERROR(IF(AND(ISNUMBER('SW Rev'!J12),ISNUMBER('SW Rev'!F12),'SW Rev'!F12>0),'SW Rev'!J12/'SW Rev'!F12-1,""),"") | G115: =IFERROR(IF(AND(ISNUMBER('SW Rev'!K12),ISNUMBER('SW Rev'!G12),'SW Rev'!G12>0),'SW Rev'!K12/'SW Rev'!G12-1,""),"") | H115: =IFERROR(IF(AND(ISNUMBER('SW Rev'!L12),ISNUMBER('SW Rev'!H12),'SW Rev'!H12>0),'SW Rev'!L12/'SW Rev'!H12-1,""),"") | I115: =IFERROR(IF(AND(ISNUMBER('SW Rev'!M12),ISNUMBER('SW Rev'!I12),'SW Rev'!I12>0),'SW Rev'!M12/'SW Rev'!I12-1,""),"") | J115: =IFERROR(IF(AND(ISNUMBER('SW Rev'!N12),ISNUMBER('SW Rev'!J12),'SW Rev'!J12>0),'SW Rev'!N12/'SW Rev'!J12-1,""),"") | ... N115: =IFERROR(IF(AND(ISNUMBER('SW Rev'!R12),ISNUMBER('SW Rev'!N12),'SW Rev'!N12>0),'SW Rev'!R12/'SW Rev'!N12-1,""),"")
A116: ='SW Rev'!$A13 | B116: ='SW Rev'!$B13 | C116: =IFERROR(IF(AND(ISNUMBER('SW Rev'!G13),ISNUMBER('SW Rev'!C13),'SW Rev'!C13>0),'SW Rev'!G13/'SW Rev'!C13-1,""),"") | D116: =IFERROR(IF(AND(ISNUMBER('SW Rev'!H13),ISNUMBER('SW Rev'!D13),'SW Rev'!D13>0),'SW Rev'!H13/'SW Rev'!D13-1,""),"") | E116: =IFERROR(IF(AND(ISNUMBER('SW Rev'!I13),ISNUMBER('SW Rev'!E13),'SW Rev'!E13>0),'SW Rev'!I13/'SW Rev'!E13-1,""),"") | F116: =IFERROR(IF(AND(ISNUMBER('SW Rev'!J13),ISNUMBER('SW Rev'!F13),'SW Rev'!F13>0),'SW Rev'!J13/'SW Rev'!F13-1,""),"") | G116: =IFERROR(IF(AND(ISNUMBER('SW Rev'!K13),ISNUMBER('SW Rev'!G13),'SW Rev'!G13>0),'SW Rev'!K13/'SW Rev'!G13-1,""),"") | H116: =IFERROR(IF(AND(ISNUMBER('SW Rev'!L13),ISNUMBER('SW Rev'!H13),'SW Rev'!H13>0),'SW Rev'!L13/'SW Rev'!H13-1,""),"") | I116: =IFERROR(IF(AND(ISNUMBER('SW Rev'!M13),ISNUMBER('SW Rev'!I13),'SW Rev'!I13>0),'SW Rev'!M13/'SW Rev'!I13-1,""),"") | J116: =IFERROR(IF(AND(ISNUMBER('SW Rev'!N13),ISNUMBER('SW Rev'!J13),'SW Rev'!J13>0),'SW Rev'!N13/'SW Rev'!J13-1,""),"") | ... N116: =IFERROR(IF(AND(ISNUMBER('SW Rev'!R13),ISNUMBER('SW Rev'!N13),'SW Rev'!N13>0),'SW Rev'!R13/'SW Rev'!N13-1,""),"")
